Workbook

Sheet Yillik_Rapor
A1: 2026 YILI PERSONEL PUANTAJ VE MESAİ İCMAL RAPORU
A2: Bu sayfadaki tüm değerler aylık puantaj sayfalarına bağlı formüllerdir; elle değer girmeyiniz. Devamsızlık = '-' (gelmediği gün) sayısı.
A4: TOPLAM PERSONEL | C4: TOPLAM ÇALIŞILAN GÜN | E4: TOPLAM DEVAMSIZLIK | F4: TOPLAM MESAİ (SAAT)
A5: =COUNTA(Personel_Listesi!A5:A19) | C5: =SUMIF($D$9:$D$203,"YILLIK TOPLAM",$E$9:$E$203) | E5: =SUMIF($D$9:$D$203,"YILLIK TOPLAM",$F$9:$F$203) | F5: =SUMIF($D$9:$D$203,"YILLIK TOPLAM",$G$9:$G$203)
A7: Sicil No | B7: Ad Soyad | C7: Departman | D7: Ay | E7: Toplam Çalışılan Gün | F7: Toplam Devamsızlık | G7: Toplam Mesai (Saat)
A9: ='Ocak'!$A$6 | B9: ='Ocak'!$B$6 | C9: ='Ocak'!$C$6 | D9: =IF('Ocak'!$A$6="","","Ocak") | E9: ='Ocak'!$BQ$6 | F9: ='Ocak'!$BP$6 | G9: ='Ocak'!$BR$6
A10: ='Şubat'!$A$6 | B10: ='Şubat'!$B$6 | C10: ='Şubat'!$C$6 | D10: =IF('Şubat'!$A$6="","","Şubat") | E10: ='Şubat'!$BK$6 | F10: ='Şubat'!$BJ$6 | G10: ='Şubat'!$BL$6
A11: ='Mart'!$A$6 | B11: ='Mart'!$B$6 | C11: ='Mart'!$C$6 | D11: =IF('Mart'!$A$6="","","Mart") | E11: ='Mart'!$BQ$6 | F11: ='Mart'!$BP$6 | G11: ='Mart'!$BR$6
A12: ='Nisan'!$A$6 | B12: ='Nisan'!$B$6 | C12: ='Nisan'!$C$6 | D12: =IF('Nisan'!$A$6="","","Nisan") | E12: ='Nisan'!$BO$6 | F12: ='Nisan'!$BN$6 | G12: ='Nisan'!$BP$6
A13: ='Mayıs'!$A$6 | B13: ='Mayıs'!$B$6 | C13: ='Mayıs'!$C$6 | D13: =IF('Mayıs'!$A$6="","","Mayıs") | E13: ='Mayıs'!$BQ$6 | F13: ='Mayıs'!$BP$6 | G13: ='Mayıs'!$BR$6
A14: ='Haziran'!$A$6 | B14: ='Haziran'!$B$6 | C14: ='Haziran'!$C$6 | D14: =IF('Haziran'!$A$6="","","Haziran") | E14: ='Haziran'!$BO$6 | F14: ='Haziran'!$BN$6 | G14: ='Haziran'!$BP$6
A15: ='Temmuz'!$A$6 | B15: ='Temmuz'!$B$6 | C15: ='Temmuz'!$C$6 | D15: =IF('Temmuz'!$A$6="","","Temmuz") | E15: ='Temmuz'!$BQ$6 | F15: ='Temmuz'!$BP$6 | G15: ='Temmuz'!$BR$6
A16: ='Ağustos'!$A$6 | B16: ='Ağustos'!$B$6 | C16: ='Ağustos'!$C$6 | D16: =IF('Ağustos'!$A$6="","","Ağustos") | E16: ='Ağustos'!$BQ$6 | F16: ='Ağustos'!$BP$6 | G16: ='Ağustos'!$BR$6
A17: ='Eylül'!$A$6 | B17: ='Eylül'!$B$6 | C17: ='Eylül'!$C$6 | D17: =IF('Eylül'!$A$6="","","Eylül") | E17: ='Eylül'!$BO$6 | F17: ='Eylül'!$BN$6 | G17: ='Eylül'!$BP$6
A18: ='Ekim'!$A$6 | B18: ='Ekim'!$B$6 | C18: ='Ekim'!$C$6 | D18: =IF('Ekim'!$A$6="","","Ekim") | E18: ='Ekim'!$BQ$6 | F18: ='Ekim'!$BP$6 | G18: ='Ekim'!$BR$6
A19: ='Kasım'!$A$6 | B19: ='Kasım'!$B$6 | C19: ='Kasım'!$C$6 | D19: =IF('Kasım'!$A$6="","","Kasım") | E19: ='Kasım'!$BO$6 | F19: ='Kasım'!$BN$6 | G19: ='Kasım'!$BP$6
A20: ='Aralık'!$A$6 | B20: ='Aralık'!$B$6 | C20: ='Aralık'!$C$6 | D20: =IF('Aralık'!$A$6="","","Aralık") | E20: ='Aralık'!$BQ$6 | F20: ='Aralık'!$BP$6 | G20: ='Aralık'!$BR$6
A21: =$A$9 | B21: =$B$9 | C21: =$C$9 | D21: =IF($A$9="","","YILLIK TOPLAM") | E21: =IF($A$9="","",SUM(E9:E20)) | F21: =IF($A$9="","",SUM(F9:F20)) | G21: =IF($A$9="","",SUM(G9:G20))
A22: ='Ocak'!$A$7 | B22: ='Ocak'!$B$7 | C22: ='Ocak'!$C$7 | D22: =IF('Ocak'!$A$7="","","Ocak") | E22: ='Ocak'!$BQ$7 | F22: ='Ocak'!$BP$7 | G22: ='Ocak'!$BR$7
A23: ='Şubat'!$A$7 | B23: ='Şubat'!$B$7 | C23: ='Şubat'!$C$7 | D23: =IF('Şubat'!$A$7="","","Şubat") | E23: ='Şubat'!$BK$7 | F23: ='Şubat'!$BJ$7 | G23: ='Şubat'!$BL$7
A24: ='Mart'!$A$7 | B24: ='Mart'!$B$7 | C24: ='Mart'!$C$7 | D24: =IF('Mart'!$A$7="","","Mart") | E24: ='Mart'!$BQ$7 | F24: ='Mart'!$BP$7 | G24: ='Mart'!$BR$7
A25: ='Nisan'!$A$7 | B25: ='Nisan'!$B$7 | C25: ='Nisan'!$C$7 | D25: =IF('Nisan'!$A$7="","","Nisan") | E25: ='Nisan'!$BO$7 | F25: ='Nisan'!$BN$7 | G25: ='Nisan'!$BP$7
A26: ='Mayıs'!$A$7 | B26: ='Mayıs'!$B$7 | C26: ='Mayıs'!$C$7 | D26: =IF('Mayıs'!$A$7="","","Mayıs") | E26: ='Mayıs'!$BQ$7 | F26: ='Mayıs'!$BP$7 | G26: ='Mayıs'!$BR$7
A27: ='Haziran'!$A$7 | B27: ='Haziran'!$B$7 | C27: ='Haziran'!$C$7 | D27: =IF('Haziran'!$A$7="","","Haziran") | E27: ='Haziran'!$BO$7 | F27: ='Haziran'!$BN$7 | G27: ='Haziran'!$BP$7
A28: ='Temmuz'!$A$7 | B28: ='Temmuz'!$B$7 | C28: ='Temmuz'!$C$7 | D28: =IF('Temmuz'!$A$7="","","Temmuz") | E28: ='Temmuz'!$BQ$7 | F28: ='Temmuz'!$BP$7 | G28: ='Temmuz'!$BR$7
A29: ='Ağustos'!$A$7 | B29: ='Ağustos'!$B$7 | C29: ='Ağustos'!$C$7 | D29: =IF('Ağustos'!$A$7="","","Ağustos") | E29: ='Ağustos'!$BQ$7 | F29: ='Ağustos'!$BP$7 | G29: ='Ağustos'!$BR$7
A30: ='Eylül'!$A$7 | B30: ='Eylül'!$B$7 | C30: ='Eylül'!$C$7 | D30: =IF('Eylül'!$A$7="","","Eylül") | E30: ='Eylül'!$BO$7 | F30: ='Eylül'!$BN$7 | G30: ='Eylül'!$BP$7
A31: ='Ekim'!$A$7 | B31: ='Ekim'!$B$7 | C31: ='Ekim'!$C$7 | D31: =IF('Ekim'!$A$7="","","Ekim") | E31: ='Ekim'!$BQ$7 | F31: ='Ekim'!$BP$7 | G31: ='Ekim'!$BR$7
A32: ='Kasım'!$A$7 | B32: ='Kasım'!$B$7 | C32: ='Kasım'!$C$7 | D32: =IF('Kasım'!$A$7="","","Kasım") | E32: ='Kasım'!$BO$7 | F32: ='Kasım'!$BN$7 | G32: ='Kasım'!$BP$7
A33: ='Aralık'!$A$7 | B33: ='Aralık'!$B$7 | C33: ='Aralık'!$C$7 | D33: =IF('Aralık'!$A$7="","","Aralık") | E33: ='Aralık'!$BQ$7 | F33: ='Aralık'!$BP$7 | G33: ='Aralık'!$BR$7
A34: =$A$22 | B34: =$B$22 | C34: =$C$22 | D34: =IF($A$22="","","YILLIK TOPLAM") | E34: =IF($A$22="","",SUM(E22:E33)) | F34: =IF($A$22="","",SUM(F22:F33)) | G34: =IF($A$22="","",SUM(G22:G33))
A35: ='Ocak'!$A$8 | B35: ='Ocak'!$B$8 | C35: ='Ocak'!$C$8 | D35: =IF('Ocak'!$A$8="","","Ocak") | E35: ='Ocak'!$BQ$8 | F35: ='Ocak'!$BP$8 | G35: ='Ocak'!$BR$8
A36: ='Şubat'!$A$8 | B36: ='Şubat'!$B$8 | C36: ='Şubat'!$C$8 | D36: =IF('Şubat'!$A$8="","","Şubat") | E36: ='Şubat'!$BK$8 | F36: ='Şubat'!$BJ$8 | G36: ='Şubat'!$BL$8
A37: ='Mart'!$A$8 | B37: ='Mart'!$B$8 | C37: ='Mart'!$C$8 | D37: =IF('Mart'!$A$8="","","Mart") | E37: ='Mart'!$BQ$8 | F37: ='Mart'!$BP$8 | G37: ='Mart'!$BR$8
A38: ='Nisan'!$A$8 | B38: ='Nisan'!$B$8 | C38: ='Nisan'!$C$8 | D38: =IF('Nisan'!$A$8="","","Nisan") | E38: ='Nisan'!$BO$8 | F38: ='Nisan'!$BN$8 | G38: ='Nisan'!$BP$8
A39: ='Mayıs'!$A$8 | B39: ='Mayıs'!$B$8 | C39: ='Mayıs'!$C$8 | D39: =IF('Mayıs'!$A$8="","","Mayıs") | E39: ='Mayıs'!$BQ$8 | F39: ='Mayıs'!$BP$8 | G39: ='Mayıs'!$BR$8
A40: ='Haziran'!$A$8 | B40: ='Haziran'!$B$8 | C40: ='Haziran'!$C$8 | D40: =IF('Haziran'!$A$8="","","Haziran") | E40: ='Haziran'!$BO$8 | F40: ='Haziran'!$BN$8 | G40: ='Haziran'!$BP$8
A41: ='Temmuz'!$A$8 | B41: ='Temmuz'!$B$8 | C41: ='Temmuz'!$C$8 | D41: =IF('Temmuz'!$A$8="","","Temmuz") | E41: ='Temmuz'!$BQ$8 | F41: ='Temmuz'!$BP$8 | G41: ='Temmuz'!$BR$8
A42: ='Ağustos'!$A$8 | B42: ='Ağustos'!$B$8 | C42: ='Ağustos'!$C$8 | D42: =IF('Ağustos'!$A$8="","","Ağustos") | E42: ='Ağustos'!$BQ$8 | F42: ='Ağustos'!$BP$8 | G42: ='Ağustos'!$BR$8
A43: ='Eylül'!$A$8 | B43: ='Eylül'!$B$8 | C43: ='Eylül'!$C$8 | D43: =IF('Eylül'!$A$8="","","Eylül") | E43: ='Eylül'!$BO$8 | F43: ='Eylül'!$BN$8 | G43: ='Eylül'!$BP$8
...

Sheet Aylik_Rapor
A1: 2026 YILI AYLIK PERSONEL PUANTAJ VE MESAİ RAPORU
A3: RAPOR AYI ▸ | C3: Ocak | D3: ="Takvim gün sayısı: "&CHOOSE(MATCH($C$3,{"Ocak","Şubat","Mart","Nisan","Mayıs","Haziran","Temmuz","Ağustos","Eylül","Ekim","Kasım","Aralık"},0),31,28,31,30,31,30,31,31,30,31,30,31)&" | Ay seçimini sarı hücreden değiştirin."
A5: Sicil No | B5: Ad Soyad | C5: Departman | D5: Tam Gün | E5: Yarım Gün | F5: Gelmediği Gün | G5: Fiili Çalışılan Gün | H5: Toplam Mesai (Saat) | I5: Devam Oranı
A6: =IF(Personel_Listesi!A5="","",Personel_Listesi!A5) | B6: =IF($A6="","",UPPER(Personel_Listesi!B5)) | C6: =IF($A6="","",Personel_Listesi!C5) | D6: =IF($A6="","",CHOOSE(MATCH($C$3,{"Ocak","Şubat","Mart","Nisan","Mayıs","Haziran","Temmuz","Ağustos","Eylül","Ekim","Kasım","Aralık"},0),'Ocak'!$BN$6,'Şubat'!$BH$6,'Mart'!$BN$6,'Nisan'!$BL$6,'Mayıs'!$BN$6,'Haziran'!$BL$6,'Temmuz'!$BN$6,'Ağustos'!$BN$6,'Eylül'!$BL$6,'Ekim'!$BN$6,'Kasım'!$BL$6,'Aralık'!$BN$6)) | E6: =IF($A6="","",CHOOSE(MATCH($C$3,{"Ocak","Şubat","Mart","Nisan","Mayıs","Haziran","Temmuz","Ağustos","Eylül","Ekim","Kasım","Aralık"},0),'Ocak'!$BO$6,'Şubat'!$BI$6,'Mart'!$BO$6,'Nisan'!$BM$6,'Mayıs'!$BO$6,'Haziran'!$BM$6,'Temmuz'!$BO$6,'Ağustos'!$BO$6,'Eylül'!$BM$6,'Ekim'!$BO$6,'Kasım'!$BM$6,'Aralık'!$BO$6)) | F6: =IF($A6="","",CHOOSE(MATCH($C$3,{"Ocak","Şubat","Mart","Nisan","Mayıs","Haziran","Temmuz","Ağustos","Eylül","Ekim","Kasım","Aralık"},0),'Ocak'!$BP$6,'Şubat'!$BJ$6,'Mart'!$BP$6,'Nisan'!$BN$6,'Mayıs'!$BP$6,'Haziran'!$BN$6,'Temmuz'!$BP$6,'Ağustos'!$BP$6,'Eylül'!$BN$6,'Ekim'!$BP$6,'Kasım'!$BN$6,'Aralık'!$BP$6)) | G6: =IF($A6="","",CHOOSE(MATCH($C$3,{"Ocak","Şubat","Mart","Nisan","Mayıs","Haziran","Temmuz","Ağustos","Eylül","Ekim","Kasım","Aralık"},0),'Ocak'!$BQ$6,'Şubat'!$BK$6,'Mart'!$BQ$6,'Nisan'!$BO$6,'Mayıs'!$BQ$6,'Haziran'!$BO$6,'Temmuz'!$BQ$6,'Ağustos'!$BQ$6,'Eylül'!$BO$6,'Ekim'!$BQ$6,'Kasım'!$BO$6,'Aralık'!$BQ$6)) | H6: =IF($A6="","",CHOOSE(MATCH($C$3,{"Ocak","Şubat","Mart","Nisan","Mayıs","Haziran","Temmuz","Ağustos","Eylül","Ekim","Kasım","Aralık"},0),'Ocak'!$BR$6,'Şubat'!$BL$6,'Mart'!$BR$6,'Nisan'!$BP$6,'Mayıs'!$BR$6,'Haziran'!$BP$6,'Temmuz'!$BR$6,'Ağustos'!$BR$6,'Eylül'!$BP$6,'Ekim'!$BR$6,'Kasım'!$BP$6,'Aralık'!$BR$6)) | I6: =IF($A6="","",IF(D6+E6+F6=0,"",G6/(D6+E6+F6)))
A7: =IF(Personel_Listesi!A6="","",Personel_Listesi!A6) | B7: =IF($A7="","",UPPER(Personel_Listesi!B6)) | C7: =IF($A7="","",Personel_Listesi!C6) | D7: =IF($A7="","",CHOOSE(MATCH($C$3,{"Ocak","Şubat","Mart","Nisan","Mayıs","Haziran","Temmuz","Ağustos","Eylül","Ekim","Kasım","Aralık"},0),'Ocak'!$BN$7,'Şubat'!$BH$7,'Mart'!$BN$7,'Nisan'!$BL$7,'Mayıs'!$BN$7,'Haziran'!$BL$7,'Temmuz'!$BN$7,'Ağustos'!$BN$7,'Eylül'!$BL$7,'Ekim'!$BN$7,'Kasım'!$BL$7,'Aralık'!$BN$7)) | E7: =IF($A7="","",CHOOSE(MATCH($C$3,{"Ocak","Şubat","Mart","Nisan","Mayıs","Haziran","Temmuz","Ağustos","Eylül","Ekim","Kasım","Aralık"},0),'Ocak'!$BO$7,'Şubat'!$BI$7,'Mart'!$BO$7,'Nisan'!$BM$7,'Mayıs'!$BO$7,'Haziran'!$BM$7,'Temmuz'!$BO$7,'Ağustos'!$BO$7,'Eylül'!$BM$7,'Ekim'!$BO$7,'Kasım'!$BM$7,'Aralık'!$BO$7)) | F7: =IF($A7="","",CHOOSE(MATCH($C$3,{"Ocak","Şubat","Mart","Nisan","Mayıs","Haziran","Temmuz","Ağustos","Eylül","Ekim","Kasım","Aralık"},0),'Ocak'!$BP$7,'Şubat'!$BJ$7,'Mart'!$BP$7,'Nisan'!$BN$7,'Mayıs'!$BP$7,'Haziran'!$BN$7,'Temmuz'!$BP$7,'Ağustos'!$BP$7,'Eylül'!$BN$7,'Ekim'!$BP$7,'Kasım'!$BN$7,'Aralık'!$BP$7)) | G7: =IF($A7="","",CHOOSE(MATCH($C$3,{"Ocak","Şubat","Mart","Nisan","Mayıs","Haziran","Temmuz","Ağustos","Eylül","Ekim","Kasım","Aralık"},0),'Ocak'!$BQ$7,'Şubat'!$BK$7,'Mart'!$BQ$7,'Nisan'!$BO$7,'Mayıs'!$BQ$7,'Haziran'!$BO$7,'Temmuz'!$BQ$7,'Ağustos'!$BQ$7,'Eylül'!$BO$7,'Ekim'!$BQ$7,'Kasım'!$BO$7,'Aralık'!$BQ$7)) | H7: =IF($A7="","",CHOOSE(MATCH($C$3,{"Ocak","Şubat","Mart","Nisan","Mayıs","Haziran","Temmuz","Ağustos","Eylül","Ekim","Kasım","Aralık"},0),'Ocak'!$BR$7,'Şubat'!$BL$7,'Mart'!$BR$7,'Nisan'!$BP$7,'Mayıs'!$BR$7,'Haziran'!$BP$7,'Temmuz'!$BR$7,'Ağustos'!$BR$7,'Eylül'!$BP$7,'Ekim'!$BR$7,'Kasım'!$BP$7,'Aralık'!$BR$7)) | I7: =IF($A7="","",IF(D7+E7+F7=0,"",G7/(D7+E7+F7)))
A8: =IF(Personel_Listesi!A7="","",Personel_Listesi!A7) | B8: =IF($A8="","",UPPER(Personel_Listesi!B7)) | C8: =IF($A8="","",Personel_Listesi!C7) | D8: =IF($A8="","",CHOOSE(MATCH($C$3,{"Ocak","Şubat","Mart","Nisan","Mayıs","Haziran","Temmuz","Ağustos","Eylül","Ekim","Kasım","Aralık"},0),'Ocak'!$BN$8,'Şubat'!$BH$8,'Mart'!$BN$8,'Nisan'!$BL$8,'Mayıs'!$BN$8,'Haziran'!$BL$8,'Temmuz'!$BN$8,'Ağustos'!$BN$8,'Eylül'!$BL$8,'Ekim'!$BN$8,'Kasım'!$BL$8,'Aralık'!$BN$8)) | E8: =IF($A8="","",CHOOSE(MATCH($C$3,{"Ocak","Şubat","Mart","Nisan","Mayıs","Haziran","Temmuz","Ağustos","Eylül","Ekim","Kasım","Aralık"},0),'Ocak'!$BO$8,'Şubat'!$BI$8,'Mart'!$BO$8,'Nisan'!$BM$8,'Mayıs'!$BO$8,'Haziran'!$BM$8,'Temmuz'!$BO$8,'Ağustos'!$BO$8,'Eylül'!$BM$8,'Ekim'!$BO$8,'Kasım'!$BM$8,'Aralık'!$BO$8)) | F8: =IF($A8="","",CHOOSE(MATCH($C$3,{"Ocak","Şubat","Mart","Nisan","Mayıs","Haziran","Temmuz","Ağustos","Eylül","Ekim","Kasım","Aralık"},0),'Ocak'!$BP$8,'Şubat'!$BJ$8,'Mart'!$BP$8,'Nisan'!$BN$8,'Mayıs'!$BP$8,'Haziran'!$BN$8,'Temmuz'!$BP$8,'Ağustos'!$BP$8,'Eylül'!$BN$8,'Ekim'!$BP$8,'Kasım'!$BN$8,'Aralık'!$BP$8)) | G8: =IF($A8="","",CHOOSE(MATCH($C$3,{"Ocak","Şubat","Mart","Nisan","Mayıs","Haziran","Temmuz","Ağustos","Eylül","Ekim","Kasım","Aralık"},0),'Ocak'!$BQ$8,'Şubat'!$BK$8,'Mart'!$BQ$8,'Nisan'!$BO$8,'Mayıs'!$BQ$8,'Haziran'!$BO$8,'Temmuz'!$BQ$8,'Ağustos'!$BQ$8,'Eylül'!$BO$8,'Ekim'!$BQ$8,'Kasım'!$BO$8,'Aralık'!$BQ$8)) | H8: =IF($A8="","",CHOOSE(MATCH($C$3,{"Ocak","Şubat","Mart","Nisan","Mayıs","Haziran","Temmuz","Ağustos","Eylül","Ekim","Kasım","Aralık"},0),'Ocak'!$BR$8,'Şubat'!$BL$8,'Mart'!$BR$8,'Nisan'!$BP$8,'Mayıs'!$BR$8,'Haziran'!$BP$8,'Temmuz'!$BR$8,'Ağustos'!$BR$8,'Eylül'!$BP$8,'Ekim'!$BR$8,'Kasım'!$BP$8,'Aralık'!$BR$8)) | I8: =IF($A8="","",IF(D8+E8+F8=0,"",G8/(D8+E8+F8)))
A9: =IF(Personel_Listesi!A8="","",Personel_Listesi!A8) | B9: =IF($A9="","",UPPER(Personel_Listesi!B8)) | C9: =IF($A9="","",Personel_Listesi!C8) | D9: =IF($A9="","",CHOOSE(MATCH($C$3,{"Ocak","Şubat","Mart","Nisan","Mayıs","Haziran","Temmuz","Ağustos","Eylül","Ekim","Kasım","Aralık"},0),'Ocak'!$BN$9,'Şubat'!$BH$9,'Mart'!$BN$9,'Nisan'!$BL$9,'Mayıs'!$BN$9,'Haziran'!$BL$9,'Temmuz'!$BN$9,'Ağustos'!$BN$9,'Eylül'!$BL$9,'Ekim'!$BN$9,'Kasım'!$BL$9,'Aralık'!$BN$9)) | E9: =IF($A9="","",CHOOSE(MATCH($C$3,{"Ocak","Şubat","Mart","Nisan","Mayıs","Haziran","Temmuz","Ağustos","Eylül","Ekim","Kasım","Aralık"},0),'Ocak'!$BO$9,'Şubat'!$BI$9,'Mart'!$BO$9,'Nisan'!$BM$9,'Mayıs'!$BO$9,'Haziran'!$BM$9,'Temmuz'!$BO$9,'Ağustos'!$BO$9,'Eylül'!$BM$9,'Ekim'!$BO$9,'Kasım'!$BM$9,'Aralık'!$BO$9)) | F9: =IF($A9="","",CHOOSE(MATCH($C$3,{"Ocak","Şubat","Mart","Nisan","Mayıs","Haziran","Temmuz","Ağustos","Eylül","Ekim","Kasım","Aralık"},0),'Ocak'!$BP$9,'Şubat'!$BJ$9,'Mart'!$BP$9,'Nisan'!$BN$9,'Mayıs'!$BP$9,'Haziran'!$BN$9,'Temmuz'!$BP$9,'Ağustos'!$BP$9,'Eylül'!$BN$9,'Ekim'!$BP$9,'Kasım'!$BN$9,'Aralık'!$BP$9)) | G9: =IF($A9="","",CHOOSE(MATCH($C$3,{"Ocak","Şubat","Mart","Nisan","Mayıs","Haziran","Temmuz","Ağustos","Eylül","Ekim","Kasım","Aralık"},0),'Ocak'!$BQ$9,'Şubat'!$BK$9,'Mart'!$BQ$9,'Nisan'!$BO$9,'Mayıs'!$BQ$9,'Haziran'!$BO$9,'Temmuz'!$BQ$9,'Ağustos'!$BQ$9,'Eylül'!$BO$9,'Ekim'!$BQ$9,'Kasım'!$BO$9,'Aralık'!$BQ$9)) | H9: =IF($A9="","",CHOOSE(MATCH($C$3,{"Ocak","Şubat","Mart","Nisan","Mayıs","Haziran","Temmuz","Ağustos","Eylül","Ekim","Kasım","Aralık"},0),'Ocak'!$BR$9,'Şubat'!$BL$9,'Mart'!$BR$9,'Nisan'!$BP$9,'Mayıs'!$BR$9,'Haziran'!$BP$9,'Temmuz'!$BR$9,'Ağustos'!$BR$9,'Eylül'!$BP$9,'Ekim'!$BR$9,'Kasım'!$BP$9,'Aralık'!$BR$9)) | I9: =IF($A9="","",IF(D9+E9+F9=0,"",G9/(D9+E9+F9)))
A10: =IF(Personel_Listesi!A9="","",Personel_Listesi!A9) | B10: =IF($A10="","",UPPER(Personel_Listesi!B9)) | C10: =IF($A10="","",Personel_Listesi!C9) | D10: =IF($A10="","",CHOOSE(MATCH($C$3,{"Ocak","Şubat","Mart","Nisan","Mayıs","Haziran","Temmuz","Ağustos","Eylül","Ekim","Kasım","Aralık"},0),'Ocak'!$BN$10,'Şubat'!$BH$10,'Mart'!$BN$10,'Nisan'!$BL$10,'Mayıs'!$BN$10,'Haziran'!$BL$10,'Temmuz'!$BN$10,'Ağustos'!$BN$10,'Eylül'!$BL$10,'Ekim'!$BN$10,'Kasım'!$BL$10,'Aralık'!$BN$10)) | E10: =IF($A10="","",CHOOSE(MATCH($C$3,{"Ocak","Şubat","Mart","Nisan","Mayıs","Haziran","Temmuz","Ağustos","Eylül","Ekim","Kasım","Aralık"},0),'Ocak'!$BO$10,'Şubat'!$BI$10,'Mart'!$BO$10,'Nisan'!$BM$10,'Mayıs'!$BO$10,'Haziran'!$BM$10,'Temmuz'!$BO$10,'Ağustos'!$BO$10,'Eylül'!$BM$10,'Ekim'!$BO$10,'Kasım'!$BM$10,'Aralık'!$BO$10)) | F10: =IF($A10="","",CHOOSE(MATCH($C$3,{"Ocak","Şubat","Mart","Nisan","Mayıs","Haziran","Temmuz","Ağustos","Eylül","Ekim","Kasım","Aralık"},0),'Ocak'!$BP$10,'Şubat'!$BJ$10,'Mart'!$BP$10,'Nisan'!$BN$10,'Mayıs'!$BP$10,'Haziran'!$BN$10,'Temmuz'!$BP$10,'Ağustos'!$BP$10,'Eylül'!$BN$10,'Ekim'!$BP$10,'Kasım'!$BN$10,'Aralık'!$BP$10)) | G10: =IF($A10="","",CHOOSE(MATCH($C$3,{"Ocak","Şubat","Mart","Nisan","Mayıs","Haziran","Temmuz","Ağustos","Eylül","Ekim","Kasım","Aralık"},0),'Ocak'!$BQ$10,'Şubat'!$BK$10,'Mart'!$BQ$10,'Nisan'!$BO$10,'Mayıs'!$BQ$10,'Haziran'!$BO$10,'Temmuz'!$BQ$10,'Ağustos'!$BQ$10,'Eylül'!$BO$10,'Ekim'!$BQ$10,'Kasım'!$BO$10,'Aralık'!$BQ$10)) | H10: =IF($A10="","",CHOOSE(MATCH($C$3,{"Ocak","Şubat","Mart","Nisan","Mayıs","Haziran","Temmuz","Ağustos","Eylül","Ekim","Kasım","Aralık"},0),'Ocak'!$BR$10,'Şubat'!$BL$10,'Mart'!$BR$10,'Nisan'!$BP$10,'Mayıs'!$BR$10,'Haziran'!$BP$10,'Temmuz'!$BR$10,'Ağustos'!$BR$10,'Eylül'!$BP$10,'Ekim'!$BR$10,'Kasım'!$BP$10,'Aralık'!$BR$10)) | I10: =IF($A10="","",IF(D10+E10+F10=0,"",G10/(D10+E10+F10)))
A11: =IF(Personel_Listesi!A10="","",Personel_Listesi!A10) | B11: =IF($A11="","",UPPER(Personel_Listesi!B10)) | C11: =IF($A11="","",Personel_Listesi!C10) | D11: =IF($A11="","",CHOOSE(MATCH($C$3,{"Ocak","Şubat","Mart","Nisan","Mayıs","Haziran","Temmuz","Ağustos","Eylül","Ekim","Kasım","Aralık"},0),'Ocak'!$BN$11,'Şubat'!$BH$11,'Mart'!$BN$11,'Nisan'!$BL$11,'Mayıs'!$BN$11,'Haziran'!$BL$11,'Temmuz'!$BN$11,'Ağustos'!$BN$11,'Eylül'!$BL$11,'Ekim'!$BN$11,'Kasım'!$BL$11,'Aralık'!$BN$11)) | E11: =IF($A11="","",CHOOSE(MATCH($C$3,{"Ocak","Şubat","Mart","Nisan","Mayıs","Haziran","Temmuz","Ağustos","Eylül","Ekim","Kasım","Aralık"},0),'Ocak'!$BO$11,'Şubat'!$BI$11,'Mart'!$BO$11,'Nisan'!$BM$11,'Mayıs'!$BO$11,'Haziran'!$BM$11,'Temmuz'!$BO$11,'Ağustos'!$BO$11,'Eylül'!$BM$11,'Ekim'!$BO$11,'Kasım'!$BM$11,'Aralık'!$BO$11)) | F11: =IF($A11="","",CHOOSE(MATCH($C$3,{"Ocak","Şubat","Mart","Nisan","Mayıs","Haziran","Temmuz","Ağustos","Eylül","Ekim","Kasım","Aralık"},0),'Ocak'!$BP$11,'Şubat'!$BJ$11,'Mart'!$BP$11,'Nisan'!$BN$11,'Mayıs'!$BP$11,'Haziran'!$BN$11,'Temmuz'!$BP$11,'Ağustos'!$BP$11,'Eylül'!$BN$11,'Ekim'!$BP$11,'Kasım'!$BN$11,'Aralık'!$BP$11)) | G11: =IF($A11="","",CHOOSE(MATCH($C$3,{"Ocak","Şubat","Mart","Nisan","Mayıs","Haziran","Temmuz","Ağustos","Eylül","Ekim","Kasım","Aralık"},0),'Ocak'!$BQ$11,'Şubat'!$BK$11,'Mart'!$BQ$11,'Nisan'!$BO$11,'Mayıs'!$BQ$11,'Haziran'!$BO$11,'Temmuz'!$BQ$11,'Ağustos'!$BQ$11,'Eylül'!$BO$11,'Ekim'!$BQ$11,'Kasım'!$BO$11,'Aralık'!$BQ$11)) | H11: =IF($A11="","",CHOOSE(MATCH($C$3,{"Ocak","Şubat","Mart","Nisan","Mayıs","Haziran","Temmuz","Ağustos","Eylül","Ekim","Kasım","Aralık"},0),'Ocak'!$BR$11,'Şubat'!$BL$11,'Mart'!$BR$11,'Nisan'!$BP$11,'Mayıs'!$BR$11,'Haziran'!$BP$11,'Temmuz'!$BR$11,'Ağustos'!$BR$11,'Eylül'!$BP$11,'Ekim'!$BR$11,'Kasım'!$BP$11,'Aralık'!$BR$11)) | I11: =IF($A11="","",IF(D11+E11+F11=0,"",G11/(D11+E11+F11)))
A12: =IF(Personel_Listesi!A11="","",Personel_Listesi!A11) | B12: =IF($A12="","",UPPER(Personel_Listesi!B11)) | C12: =IF($A12="","",Personel_Listesi!C11) | D12: =IF($A12="","",CHOOSE(MATCH($C$3,{"Ocak","Şubat","Mart","Nisan","Mayıs","Haziran","Temmuz","Ağustos","Eylül","Ekim","Kasım","Aralık"},0),'Ocak'!$BN$12,'Şubat'!$BH$12,'Mart'!$BN$12,'Nisan'!$BL$12,'Mayıs'!$BN$12,'Haziran'!$BL$12,'Temmuz'!$BN$12,'Ağustos'!$BN$12,'Eylül'!$BL$12,'Ekim'!$BN$12,'Kasım'!$BL$12,'Aralık'!$BN$12)) | E12: =IF($A12="","",CHOOSE(MATCH($C$3,{"Ocak","Şubat","Mart","Nisan","Mayıs","Haziran","Temmuz","Ağustos","Eylül","Ekim","Kasım","Aralık"},0),'Ocak'!$BO$12,'Şubat'!$BI$12,'Mart'!$BO$12,'Nisan'!$BM$12,'Mayıs'!$BO$12,'Haziran'!$BM$12,'Temmuz'!$BO$12,'Ağustos'!$BO$12,'Eylül'!$BM$12,'Ekim'!$BO$12,'Kasım'!$BM$12,'Aralık'!$BO$12)) | F12: =IF($A12="","",CHOOSE(MATCH($C$3,{"Ocak","Şubat","Mart","Nisan","Mayıs","Haziran","Temmuz","Ağustos","Eylül","Ekim","Kasım","Aralık"},0),'Ocak'!$BP$12,'Şubat'!$BJ$12,'Mart'!$BP$12,'Nisan'!$BN$12,'Mayıs'!$BP$12,'Haziran'!$BN$12,'Temmuz'!$BP$12,'Ağustos'!$BP$12,'Eylül'!$BN$12,'Ekim'!$BP$12,'Kasım'!$BN$12,'Aralık'!$BP$12)) | G12: =IF($A12="","",CHOOSE(MATCH($C$3,{"Ocak","Şubat","Mart","Nisan","Mayıs","Haziran","Temmuz","Ağustos","Eylül","Ekim","Kasım","Aralık"},0),'Ocak'!$BQ$12,'Şubat'!$BK$12,'Mart'!$BQ$12,'Nisan'!$BO$12,'Mayıs'!$BQ$12,'Haziran'!$BO$12,'Temmuz'!$BQ$12,'Ağustos'!$BQ$12,'Eylül'!$BO$12,'Ekim'!$BQ$12,'Kasım'!$BO$12,'Aralık'!$BQ$12)) | H12: =IF($A12="","",CHOOSE(MATCH($C$3,{"Ocak","Şubat","Mart","Nisan","Mayıs","Haziran","Temmuz","Ağustos","Eylül","Ekim","Kasım","Aralık"},0),'Ocak'!$BR$12,'Şubat'!$BL$12,'Mart'!$BR$12,'Nisan'!$BP$12,'Mayıs'!$BR$12,'Haziran'!$BP$12,'Temmuz'!$BR$12,'Ağustos'!$BR$12,'Eylül'!$BP$12,'Ekim'!$BR$12,'Kasım'!$BP$12,'Aralık'!$BR$12)) | I12: =IF($A12="","",IF(D12+E12+F12=0,"",G12/(D12+E12+F12)))
A13: =IF(Personel_Listesi!A12="","",Personel_Listesi!A12) | B13: =IF($A13="","",UPPER(Personel_Listesi!B12)) | C13: =IF($A13="","",Personel_Listesi!C12) | D13: =IF($A13="","",CHOOSE(MATCH($C$3,{"Ocak","Şubat","Mart","Nisan","Mayıs","Haziran","Temmuz","Ağustos","Eylül","Ekim","Kasım","Aralık"},0),'Ocak'!$BN$13,'Şubat'!$BH$13,'Mart'!$BN$13,'Nisan'!$BL$13,'Mayıs'!$BN$13,'Haziran'!$BL$13,'Temmuz'!$BN$13,'Ağustos'!$BN$13,'Eylül'!$BL$13,'Ekim'!$BN$13,'Kasım'!$BL$13,'Aralık'!$BN$13)) | E13: =IF($A13="","",CHOOSE(MATCH($C$3,{"Ocak","Şubat","Mart","Nisan","Mayıs","Haziran","Temmuz","Ağustos","Eylül","Ekim","Kasım","Aralık"},0),'Ocak'!$BO$13,'Şubat'!$BI$13,'Mart'!$BO$13,'Nisan'!$BM$13,'Mayıs'!$BO$13,'Haziran'!$BM$13,'Temmuz'!$BO$13,'Ağustos'!$BO$13,'Eylül'!$BM$13,'Ekim'!$BO$13,'Kasım'!$BM$13,'Aralık'!$BO$13)) | F13: =IF($A13="","",CHOOSE(MATCH($C$3,{"Ocak","Şubat","Mart","Nisan","Mayıs","Haziran","Temmuz","Ağustos","Eylül","Ekim","Kasım","Aralık"},0),'Ocak'!$BP$13,'Şubat'!$BJ$13,'Mart'!$BP$13,'Nisan'!$BN$13,'Mayıs'!$BP$13,'Haziran'!$BN$13,'Temmuz'!$BP$13,'Ağustos'!$BP$13,'Eylül'!$BN$13,'Ekim'!$BP$13,'Kasım'!$BN$13,'Aralık'!$BP$13)) | G13: =IF($A13="","",CHOOSE(MATCH($C$3,{"Ocak","Şubat","Mart","Nisan","Mayıs","Haziran","Temmuz","Ağustos","Eylül","Ekim","Kasım","Aralık"},0),'Ocak'!$BQ$13,'Şubat'!$BK$13,'Mart'!$BQ$13,'Nisan'!$BO$13,'Mayıs'!$BQ$13,'Haziran'!$BO$13,'Temmuz'!$BQ$13,'Ağustos'!$BQ$13,'Eylül'!$BO$13,'Ekim'!$BQ$13,'Kasım'!$BO$13,'Aralık'!$BQ$13)) | H13: =IF($A13="","",CHOOSE(MATCH($C$3,{"Ocak","Şubat","Mart","Nisan","Mayıs","Haziran","Temmuz","Ağustos","Eylül","Ekim","Kasım","Aralık"},0),'Ocak'!$BR$13,'Şubat'!$BL$13,'Mart'!$BR$13,'Nisan'!$BP$13,'Mayıs'!$BR$13,'Haziran'!$BP$13,'Temmuz'!$BR$13,'Ağustos'!$BR$13,'Eylül'!$BP$13,'Ekim'!$BR$13,'Kasım'!$BP$13,'Aralık'!$BR$13)) | I13: =IF($A13="","",IF(D13+E13+F13=0,"",G13/(D13+E13+F13)))
A14: =IF(Personel_Listesi!A13="","",Personel_Listesi!A13) | B14: =IF($A14="","",UPPER(Personel_Listesi!B13)) | C14: =IF($A14="","",Personel_Listesi!C13) | D14: =IF($A14="","",CHOOSE(MATCH($C$3,{"Ocak","Şubat","Mart","Nisan","Mayıs","Haziran","Temmuz","Ağustos","Eylül","Ekim","Kasım","Aralık"},0),'Ocak'!$BN$14,'Şubat'!$BH$14,'Mart'!$BN$14,'Nisan'!$BL$14,'Mayıs'!$BN$14,'Haziran'!$BL$14,'Temmuz'!$BN$14,'Ağustos'!$BN$14,'Eylül'!$BL$14,'Ekim'!$BN$14,'Kasım'!$BL$14,'Aralık'!$BN$14)) | E14: =IF($A14="","",CHOOSE(MATCH($C$3,{"Ocak","Şubat","Mart","Nisan","Mayıs","Haziran","Temmuz","Ağustos","Eylül","Ekim","Kasım","Aralık"},0),'Ocak'!$BO$14,'Şubat'!$BI$14,'Mart'!$BO$14,'Nisan'!$BM$14,'Mayıs'!$BO$14,'Haziran'!$BM$14,'Temmuz'!$BO$14,'Ağustos'!$BO$14,'Eylül'!$BM$14,'Ekim'!$BO$14,'Kasım'!$BM$14,'Aralık'!$BO$14)) | F14: =IF($A14="","",CHOOSE(MATCH($C$3,{"Ocak","Şubat","Mart","Nisan","Mayıs","Haziran","Temmuz","Ağustos","Eylül","Ekim","Kasım","Aralık"},0),'Ocak'!$BP$14,'Şubat'!$BJ$14,'Mart'!$BP$14,'Nisan'!$BN$14,'Mayıs'!$BP$14,'Haziran'!$BN$14,'Temmuz'!$BP$14,'Ağustos'!$BP$14,'Eylül'!$BN$14,'Ekim'!$BP$14,'Kasım'!$BN$14,'Aralık'!$BP$14)) | G14: =IF($A14="","",CHOOSE(MATCH($C$3,{"Ocak","Şubat","Mart","Nisan","Mayıs","Haziran","Temmuz","Ağustos","Eylül","Ekim","Kasım","Aralık"},0),'Ocak'!$BQ$14,'Şubat'!$BK$14,'Mart'!$BQ$14,'Nisan'!$BO$14,'Mayıs'!$BQ$14,'Haziran'!$BO$14,'Temmuz'!$BQ$14,'Ağustos'!$BQ$14,'Eylül'!$BO$14,'Ekim'!$BQ$14,'Kasım'!$BO$14,'Aralık'!$BQ$14)) | H14: =IF($A14="","",CHOOSE(MATCH($C$3,{"Ocak","Şubat","Mart","Nisan","Mayıs","Haziran","Temmuz","Ağustos","Eylül","Ekim","Kasım","Aralık"},0),'Ocak'!$BR$14,'Şubat'!$BL$14,'Mart'!$BR$14,'Nisan'!$BP$14,'Mayıs'!$BR$14,'Haziran'!$BP$14,'Temmuz'!$BR$14,'Ağustos'!$BR$14,'Eylül'!$BP$14,'Ekim'!$BR$14,'Kasım'!$BP$14,'Aralık'!$BR$14)) | I14: =IF($A14="","",IF(D14+E14+F14=0,"",G14/(D14+E14+F14)))
A15: =IF(Personel_Listesi!A14="","",Personel_Listesi!A14) | B15: =IF($A15="","",UPPER(Personel_Listesi!B14)) | C15: =IF($A15="","",Personel_Listesi!C14) | D15: =IF($A15="","",CHOOSE(MATCH($C$3,{"Ocak","Şubat","Mart","Nisan","Mayıs","Haziran","Temmuz","Ağustos","Eylül","Ekim","Kasım","Aralık"},0),'Ocak'!$BN$15,'Şubat'!$BH$15,'Mart'!$BN$15,'Nisan'!$BL$15,'Mayıs'!$BN$15,'Haziran'!$BL$15,'Temmuz'!$BN$15,'Ağustos'!$BN$15,'Eylül'!$BL$15,'Ekim'!$BN$15,'Kasım'!$BL$15,'Aralık'!$BN$15)) | E15: =IF($A15="","",CHOOSE(MATCH($C$3,{"Ocak","Şubat","Mart","Nisan","Mayıs","Haziran","Temmuz","Ağustos","Eylül","Ekim","Kasım","Aralık"},0),'Ocak'!$BO$15,'Şubat'!$BI$15,'Mart'!$BO$15,'Nisan'!$BM$15,'Mayıs'!$BO$15,'Haziran'!$BM$15,'Temmuz'!$BO$15,'Ağustos'!$BO$15,'Eylül'!$BM$15,'Ekim'!$BO$15,'Kasım'!$BM$15,'Aralık'!$BO$15)) | F15: =IF($A15="","",CHOOSE(MATCH($C$3,{"Ocak","Şubat","Mart","Nisan","Mayıs","Haziran","Temmuz","Ağustos","Eylül","Ekim","Kasım","Aralık"},0),'Ocak'!$BP$15,'Şubat'!$BJ$15,'Mart'!$BP$15,'Nisan'!$BN$15,'Mayıs'!$BP$15,'Haziran'!$BN$15,'Temmuz'!$BP$15,'Ağustos'!$BP$15,'Eylül'!$BN$15,'Ekim'!$BP$15,'Kasım'!$BN$15,'Aralık'!$BP$15)) | G15: =IF($A15="","",CHOOSE(MATCH($C$3,{"Ocak","Şubat","Mart","Nisan","Mayıs","Haziran","Temmuz","Ağustos","Eylül","Ekim","Kasım","Aralık"},0),'Ocak'!$BQ$15,'Şubat'!$BK$15,'Mart'!$BQ$15,'Nisan'!$BO$15,'Mayıs'!$BQ$15,'Haziran'!$BO$15,'Temmuz'!$BQ$15,'Ağustos'!$BQ$15,'Eylül'!$BO$15,'Ekim'!$BQ$15,'Kasım'!$BO$15,'Aralık'!$BQ$15)) | H15: =IF($A15="","",CHOOSE(MATCH($C$3,{"Ocak","Şubat","Mart","Nisan","Mayıs","Haziran","Temmuz","Ağustos","Eylül","Ekim","Kasım","Aralık"},0),'Ocak'!$BR$15,'Şubat'!$BL$15,'Mart'!$BR$15,'Nisan'!$BP$15,'Mayıs'!$BR$15,'Haziran'!$BP$15,'Temmuz'!$BR$15,'Ağustos'!$BR$15,'Eylül'!$BP$15,'Ekim'!$BR$15,'Kasım'!$BP$15,'Aralık'!$BR$15)) | I15: =IF($A15="","",IF(D15+E15+F15=0,"",G15/(D15+E15+F15)))
A16: =IF(Personel_Listesi!A15="","",Personel_Listesi!A15) | B16: =IF($A16="","",UPPER(Personel_Listesi!B15)) | C16: =IF($A16="","",Personel_Listesi!C15) | D16: =IF($A16="","",CHOOSE(MATCH($C$3,{"Ocak","Şubat","Mart","Nisan","Mayıs","Haziran","Temmuz","Ağustos","Eylül","Ekim","Kasım","Aralık"},0),'Ocak'!$BN$16,'Şubat'!$BH$16,'Mart'!$BN$16,'Nisan'!$BL$16,'Mayıs'!$BN$16,'Haziran'!$BL$16,'Temmuz'!$BN$16,'Ağustos'!$BN$16,'Eylül'!$BL$16,'Ekim'!$BN$16,'Kasım'!$BL$16,'Aralık'!$BN$16)) | E16: =IF($A16="","",CHOOSE(MATCH($C$3,{"Ocak","Şubat","Mart","Nisan","Mayıs","Haziran","Temmuz","Ağustos","Eylül","Ekim","Kasım","Aralık"},0),'Ocak'!$BO$16,'Şubat'!$BI$16,'Mart'!$BO$16,'Nisan'!$BM$16,'Mayıs'!$BO$16,'Haziran'!$BM$16,'Temmuz'!$BO$16,'Ağustos'!$BO$16,'Eylül'!$BM$16,'Ekim'!$BO$16,'Kasım'!$BM$16,'Aralık'!$BO$16)) | F16: =IF($A16="","",CHOOSE(MATCH($C$3,{"Ocak","Şubat","Mart","Nisan","Mayıs","Haziran","Temmuz","Ağustos","Eylül","Ekim","Kasım","Aralık"},0),'Ocak'!$BP$16,'Şubat'!$BJ$16,'Mart'!$BP$16,'Nisan'!$BN$16,'Mayıs'!$BP$16,'Haziran'!$BN$16,'Temmuz'!$BP$16,'Ağustos'!$BP$16,'Eylül'!$BN$16,'Ekim'!$BP$16,'Kasım'!$BN$16,'Aralık'!$BP$16)) | G16: =IF($A16="","",CHOOSE(MATCH($C$3,{"Ocak","Şubat","Mart","Nisan","Mayıs","Haziran","Temmuz","Ağustos","Eylül","Ekim","Kasım","Aralık"},0),'Ocak'!$BQ$16,'Şubat'!$BK$16,'Mart'!$BQ$16,'Nisan'!$BO$16,'Mayıs'!$BQ$16,'Haziran'!$BO$16,'Temmuz'!$BQ$16,'Ağustos'!$BQ$16,'Eylül'!$BO$16,'Ekim'!$BQ$16,'Kasım'!$BO$16,'Aralık'!$BQ$16)) | H16: =IF($A16="","",CHOOSE(MATCH($C$3,{"Ocak","Şubat","Mart","Nisan","Mayıs","Haziran","Temmuz","Ağustos","Eylül","Ekim","Kasım","Aralık"},0),'Ocak'!$BR$16,'Şubat'!$BL$16,'Mart'!$BR$16,'Nisan'!$BP$16,'Mayıs'!$BR$16,'Haziran'!$BP$16,'Temmuz'!$BR$16,'Ağustos'!$BR$16,'Eylül'!$BP$16,'Ekim'!$BR$16,'Kasım'!$BP$16,'Aralık'!$BR$16)) | I16: =IF($A16="","",IF(D16+E16+F16=0,"",G16/(D16+E16+F16)))
A17: =IF(Personel_Listesi!A16="","",Personel_Listesi!A16) | B17: =IF($A17="","",UPPER(Personel_Listesi!B16)) | C17: =IF($A17="","",Personel_Listesi!C16) | D17: =IF($A17="","",CHOOSE(MATCH($C$3,{"Ocak","Şubat","Mart","Nisan","Mayıs","Haziran","Temmuz","Ağustos","Eylül","Ekim","Kasım","Aralık"},0),'Ocak'!$BN$17,'Şubat'!$BH$17,'Mart'!$BN$17,'Nisan'!$BL$17,'Mayıs'!$BN$17,'Haziran'!$BL$17,'Temmuz'!$BN$17,'Ağustos'!$BN$17,'Eylül'!$BL$17,'Ekim'!$BN$17,'Kasım'!$BL$17,'Aralık'!$BN$17)) | E17: =IF($A17="","",CHOOSE(MATCH($C$3,{"Ocak","Şubat","Mart","Nisan","Mayıs","Haziran","Temmuz","Ağustos","Eylül","Ekim","Kasım","Aralık"},0),'Ocak'!$BO$17,'Şubat'!$BI$17,'Mart'!$BO$17,'Nisan'!$BM$17,'Mayıs'!$BO$17,'Haziran'!$BM$17,'Temmuz'!$BO$17,'Ağustos'!$BO$17,'Eylül'!$BM$17,'Ekim'!$BO$17,'Kasım'!$BM$17,'Aralık'!$BO$17)) | F17: =IF($A17="","",CHOOSE(MATCH($C$3,{"Ocak","Şubat","Mart","Nisan","Mayıs","Haziran","Temmuz","Ağustos","Eylül","Ekim","Kasım","Aralık"},0),'Ocak'!$BP$17,'Şubat'!$BJ$17,'Mart'!$BP$17,'Nisan'!$BN$17,'Mayıs'!$BP$17,'Haziran'!$BN$17,'Temmuz'!$BP$17,'Ağustos'!$BP$17,'Eylül'!$BN$17,'Ekim'!$BP$17,'Kasım'!$BN$17,'Aralık'!$BP$17)) | G17: =IF($A17="","",CHOOSE(MATCH($C$3,{"Ocak","Şubat","Mart","Nisan","Mayıs","Haziran","Temmuz","Ağustos","Eylül","Ekim","Kasım","Aralık"},0),'Ocak'!$BQ$17,'Şubat'!$BK$17,'Mart'!$BQ$17,'Nisan'!$BO$17,'Mayıs'!$BQ$17,'Haziran'!$BO$17,'Temmuz'!$BQ$17,'Ağustos'!$BQ$17,'Eylül'!$BO$17,'Ekim'!$BQ$17,'Kasım'!$BO$17,'Aralık'!$BQ$17)) | H17: =IF($A17="","",CHOOSE(MATCH($C$3,{"Ocak","Şubat","Mart","Nisan","Mayıs","Haziran","Temmuz","Ağustos","Eylül","Ekim","Kasım","Aralık"},0),'Ocak'!$BR$17,'Şubat'!$BL$17,'Mart'!$BR$17,'Nisan'!$BP$17,'Mayıs'!$BR$17,'Haziran'!$BP$17,'Temmuz'!$BR$17,'Ağustos'!$BR$17,'Eylül'!$BP$17,'Ekim'!$BR$17,'Kasım'!$BP$17,'Aralık'!$BR$17)) | I17: =IF($A17="","",IF(D17+E17+F17=0,"",G17/(D17+E17+F17)))
A18: =IF(Personel_Listesi!A17="","",Personel_Listesi!A17) | B18: =IF($A18="","",UPPER(Personel_Listesi!B17)) | C18: =IF($A18="","",Personel_Listesi!C17) | D18: =IF($A18="","",CHOOSE(MATCH($C$3,{"Ocak","Şubat","Mart","Nisan","Mayıs","Haziran","Temmuz","Ağustos","Eylül","Ekim","Kasım","Aralık"},0),'Ocak'!$BN$18,'Şubat'!$BH$18,'Mart'!$BN$18,'Nisan'!$BL$18,'Mayıs'!$BN$18,'Haziran'!$BL$18,'Temmuz'!$BN$18,'Ağustos'!$BN$18,'Eylül'!$BL$18,'Ekim'!$BN$18,'Kasım'!$BL$18,'Aralık'!$BN$18)) | E18: =IF($A18="","",CHOOSE(MATCH($C$3,{"Ocak","Şubat","Mart","Nisan","Mayıs","Haziran","Temmuz","Ağustos","Eylül","Ekim","Kasım","Aralık"},0),'Ocak'!$BO$18,'Şubat'!$BI$18,'Mart'!$BO$18,'Nisan'!$BM$18,'Mayıs'!$BO$18,'Haziran'!$BM$18,'Temmuz'!$BO$18,'Ağustos'!$BO$18,'Eylül'!$BM$18,'Ekim'!$BO$18,'Kasım'!$BM$18,'Aralık'!$BO$18)) | F18: =IF($A18="","",CHOOSE(MATCH($C$3,{"Ocak","Şubat","Mart","Nisan","Mayıs","Haziran","Temmuz","Ağustos","Eylül","Ekim","Kasım","Aralık"},0),'Ocak'!$BP$18,'Şubat'!$BJ$18,'Mart'!$BP$18,'Nisan'!$BN$18,'Mayıs'!$BP$18,'Haziran'!$BN$18,'Temmuz'!$BP$18,'Ağustos'!$BP$18,'Eylül'!$BN$18,'Ekim'!$BP$18,'Kasım'!$BN$18,'Aralık'!$BP$18)) | G18: =IF($A18="","",CHOOSE(MATCH($C$3,{"Ocak","Şubat","Mart","Nisan","Mayıs","Haziran","Temmuz","Ağustos","Eylül","Ekim","Kasım","Aralık"},0),'Ocak'!$BQ$18,'Şubat'!$BK$18,'Mart'!$BQ$18,'Nisan'!$BO$18,'Mayıs'!$BQ$18,'Haziran'!$BO$18,'Temmuz'!$BQ$18,'Ağustos'!$BQ$18,'Eylül'!$BO$18,'Ekim'!$BQ$18,'Kasım'!$BO$18,'Aralık'!$BQ$18)) | H18: =IF($A18="","",CHOOSE(MATCH($C$3,{"Ocak","Şubat","Mart","Nisan","Mayıs","Haziran","Temmuz","Ağustos","Eylül","Ekim","Kasım","Aralık"},0),'Ocak'!$BR$18,'Şubat'!$BL$18,'Mart'!$BR$18,'Nisan'!$BP$18,'Mayıs'!$BR$18,'Haziran'!$BP$18,'Temmuz'!$BR$18,'Ağustos'!$BR$18,'Eylül'!$BP$18,'Ekim'!$BR$18,'Kasım'!$BP$18,'Aralık'!$BR$18)) | I18: =IF($A18="","",IF(D18+E18+F18=0,"",G18/(D18+E18+F18)))
A19: =IF(Personel_Listesi!A18="","",Personel_Listesi!A18) | B19: =IF($A19="","",UPPER(Personel_Listesi!B18)) | C19: =IF($A19="","",Personel_Listesi!C18) | D19: =IF($A19="","",CHOOSE(MATCH($C$3,{"Ocak","Şubat","Mart","Nisan","Mayıs","Haziran","Temmuz","Ağustos","Eylül","Ekim","Kasım","Aralık"},0),'Ocak'!$BN$19,'Şubat'!$BH$19,'Mart'!$BN$19,'Nisan'!$BL$19,'Mayıs'!$BN$19,'Haziran'!$BL$19,'Temmuz'!$BN$19,'Ağustos'!$BN$19,'Eylül'!$BL$19,'Ekim'!$BN$19,'Kasım'!$BL$19,'Aralık'!$BN$19)) | E19: =IF($A19="","",CHOOSE(MATCH($C$3,{"Ocak","Şubat","Mart","Nisan","Mayıs","Haziran","Temmuz","Ağustos","Eylül","Ekim","Kasım","Aralık"},0),'Ocak'!$BO$19,'Şubat'!$BI$19,'Mart'!$BO$19,'Nisan'!$BM$19,'Mayıs'!$BO$19,'Haziran'!$BM$19,'Temmuz'!$BO$19,'Ağustos'!$BO$19,'Eylül'!$BM$19,'Ekim'!$BO$19,'Kasım'!$BM$19,'Aralık'!$BO$19)) | F19: =IF($A19="","",CHOOSE(MATCH($C$3,{"Ocak","Şubat","Mart","Nisan","Mayıs","Haziran","Temmuz","Ağustos","Eylül","Ekim","Kasım","Aralık"},0),'Ocak'!$BP$19,'Şubat'!$BJ$19,'Mart'!$BP$19,'Nisan'!$BN$19,'Mayıs'!$BP$19,'Haziran'!$BN$19,'Temmuz'!$BP$19,'Ağustos'!$BP$19,'Eylül'!$BN$19,'Ekim'!$BP$19,'Kasım'!$BN$19,'Aralık'!$BP$19)) | G19: =IF($A19="","",CHOOSE(MATCH($C$3,{"Ocak","Şubat","Mart","Nisan","Mayıs","Haziran","Temmuz","Ağustos","Eylül","Ekim","Kasım","Aralık"},0),'Ocak'!$BQ$19,'Şubat'!$BK$19,'Mart'!$BQ$19,'Nisan'!$BO$19,'Mayıs'!$BQ$19,'Haziran'!$BO$19,'Temmuz'!$BQ$19,'Ağustos'!$BQ$19,'Eylül'!$BO$19,'Ekim'!$BQ$19,'Kasım'!$BO$19,'Aralık'!$BQ$19)) | H19: =IF($A19="","",CHOOSE(MATCH($C$3,{"Ocak","Şubat","Mart","Nisan","Mayıs","Haziran","Temmuz","Ağustos","Eylül","Ekim","Kasım","Aralık"},0),'Ocak'!$BR$19,'Şubat'!$BL$19,'Mart'!$BR$19,'Nisan'!$BP$19,'Mayıs'!$BR$19,'Haziran'!$BP$19,'Temmuz'!$BR$19,'Ağustos'!$BR$19,'Eylül'!$BP$19,'Ekim'!$BR$19,'Kasım'!$BP$19,'Aralık'!$BR$19)) | I19: =IF($A19="","",IF(D19+E19+F19=0,"",G19/(D19+E19+F19)))
A20: =IF(Personel_Listesi!A19="","",Personel_Listesi!A19) | B20: =IF($A20="","",UPPER(Personel_Listesi!B19)) | C20: =IF($A20="","",Personel_Listesi!C19) | D20: =IF($A20="","",CHOOSE(MATCH($C$3,{"Ocak","Şubat","Mart","Nisan","Mayıs","Haziran","Temmuz","Ağustos","Eylül","Ekim","Kasım","Aralık"},0),'Ocak'!$BN$20,'Şubat'!$BH$20,'Mart'!$BN$20,'Nisan'!$BL$20,'Mayıs'!$BN$20,'Haziran'!$BL$20,'Temmuz'!$BN$20,'Ağustos'!$BN$20,'Eylül'!$BL$20,'Ekim'!$BN$20,'Kasım'!$BL$20,'Aralık'!$BN$20)) | E20: =IF($A20="","",CHOOSE(MATCH($C$3,{"Ocak","Şubat","Mart","Nisan","Mayıs","Haziran","Temmuz","Ağustos","Eylül","Ekim","Kasım","Aralık"},0),'Ocak'!$BO$20,'Şubat'!$BI$20,'Mart'!$BO$20,'Nisan'!$BM$20,'Mayıs'!$BO$20,'Haziran'!$BM$20,'Temmuz'!$BO$20,'Ağustos'!$BO$20,'Eylül'!$BM$20,'Ekim'!$BO$20,'Kasım'!$BM$20,'Aralık'!$BO$20)) | F20: =IF($A20="","",CHOOSE(MATCH($C$3,{"Ocak","Şubat","Mart","Nisan","Mayıs","Haziran","Temmuz","Ağustos","Eylül","Ekim","Kasım","Aralık"},0),'Ocak'!$BP$20,'Şubat'!$BJ$20,'Mart'!$BP$20,'Nisan'!$BN$20,'Mayıs'!$BP$20,'Haziran'!$BN$20,'Temmuz'!$BP$20,'Ağustos'!$BP$20,'Eylül'!$BN$20,'Ekim'!$BP$20,'Kasım'!$BN$20,'Aralık'!$BP$20)) | G20: =IF($A20="","",CHOOSE(MATCH($C$3,{"Ocak","Şubat","Mart","Nisan","Mayıs","Haziran","Temmuz","Ağustos","Eylül","Ekim","Kasım","Aralık"},0),'Ocak'!$BQ$20,'Şubat'!$BK$20,'Mart'!$BQ$20,'Nisan'!$BO$20,'Mayıs'!$BQ$20,'Haziran'!$BO$20,'Temmuz'!$BQ$20,'Ağustos'!$BQ$20,'Eylül'!$BO$20,'Ekim'!$BQ$20,'Kasım'!$BO$20,'Aralık'!$BQ$20)) | H20: =IF($A20="","",CHOOSE(MATCH($C$3,{"Ocak","Şubat","Mart","Nisan","Mayıs","Haziran","Temmuz","Ağustos","Eylül","Ekim","Kasım","Aralık"},0),'Ocak'!$BR$20,'Şubat'!$BL$20,'Mart'!$BR$20,'Nisan'!$BP$20,'Mayıs'!$BR$20,'Haziran'!$BP$20,'Temmuz'!$BR$20,'Ağustos'!$BR$20,'Eylül'!$BP$20,'Ekim'!$BR$20,'Kasım'!$BP$20,'Aralık'!$BR$20)) | I20: =IF($A20="","",IF(D20+E20+F20=0,"",G20/(D20+E20+F20)))
A21: AY TOPLAMI | D21: =SUM(D6:D20) | E21: =SUM(E6:E20) | F21: =SUM(F6:F20) | G21: =SUM(G6:G20) | H21: =SUM(H6:H20) | I21: =IF(D21+E21+F21=0,"",G21/(D21+E21+F21))
A24: AYLARA GÖRE KARŞILAŞTIRMA (TÜM PERSONEL)
A25: Ay | C25: Takvim Günü | D25: Tam Gün | E25: Yarım Gün | F25: Gelmediği Gün | G25: Fiili Çalışılan Gün | H25: Toplam Mesai (Saat) | I25: Devam Oranı
A26: Ocak | C26: 31 | D26: =SUM('Ocak'!BN6:BN20) | E26: =SUM('Ocak'!BO6:BO20) | F26: =SUM('Ocak'!BP6:BP20) | G26: =SUM('Ocak'!BQ6:BQ20) | H26: =SUM('Ocak'!BR6:BR20) | I26: =IF(D26+E26+F26=0,"",G26/(D26+E26+F26))
A27: Şubat | C27: 28 | D27: =SUM('Şubat'!BH6:BH20) | E27: =SUM('Şubat'!BI6:BI20) | F27: =SUM('Şubat'!BJ6:BJ20) | G27: =SUM('Şubat'!BK6:BK20) | H27: =SUM('Şubat'!BL6:BL20) | I27: =IF(D27+E27+F27=0,"",G27/(D27+E27+F27))
A28: Mart | C28: 31 | D28: =SUM('Mart'!BN6:BN20) | E28: =SUM('Mart'!BO6:BO20) | F28: =SUM('Mart'!BP6:BP20) | G28: =SUM('Mart'!BQ6:BQ20) | H28: =SUM('Mart'!BR6:BR20) | I28: =IF(D28+E28+F28=0,"",G28/(D28+E28+F28))
A29: Nisan | C29: 30 | D29: =SUM('Nisan'!BL6:BL20) | E29: =SUM('Nisan'!BM6:BM20) | F29: =SUM('Nisan'!BN6:BN20) | G29: =SUM('Nisan'!BO6:BO20) | H29: =SUM('Nisan'!BP6:BP20) | I29: =IF(D29+E29+F29=0,"",G29/(D29+E29+F29))
A30: Mayıs | C30: 31 | D30: =SUM('Mayıs'!BN6:BN20) | E30: =SUM('Mayıs'!BO6:BO20) | F30: =SUM('Mayıs'!BP6:BP20) | G30: =SUM('Mayıs'!BQ6:BQ20) | H30: =SUM('Mayıs'!BR6:BR20) | I30: =IF(D30+E30+F30=0,"",G30/(D30+E30+F30))
A31: Haziran | C31: 30 | D31: =SUM('Haziran'!BL6:BL20) | E31: =SUM('Haziran'!BM6:BM20) | F31: =SUM('Haziran'!BN6:BN20) | G31: =SUM('Haziran'!BO6:BO20) | H31: =SUM('Haziran'!BP6:BP20) | I31: =IF(D31+E31+F31=0,"",G31/(D31+E31+F31))
A32: Temmuz | C32: 31 | D32: =SUM('Temmuz'!BN6:BN20) | E32: =SUM('Temmuz'!BO6:BO20) | F32: =SUM('Temmuz'!BP6:BP20) | G32: =SUM('Temmuz'!BQ6:BQ20) | H32: =SUM('Temmuz'!BR6:BR20) | I32: =IF(D32+E32+F32=0,"",G32/(D32+E32+F32))
A33: Ağustos | C33: 31 | D33: =SUM('Ağustos'!BN6:BN20) | E33: =SUM('Ağustos'!BO6:BO20) | F33: =SUM('Ağustos'!BP6:BP20) | G33: =SUM('Ağustos'!BQ6:BQ20) | H33: =SUM('Ağustos'!BR6:BR20) | I33: =IF(D33+E33+F33=0,"",G33/(D33+E33+F33))
A34: Eylül | C34: 30 | D34: =SUM('Eylül'!BL6:BL20) | E34: =SUM('Eylül'!BM6:BM20) | F34: =SUM('Eylül'!BN6:BN20) | G34: =SUM('Eylül'!BO6:BO20) | H34: =SUM('Eylül'!BP6:BP20) | I34: =IF(D34+E34+F34=0,"",G34/(D34+E34+F34))
A35: Ekim | C35: 31 | D35: =SUM('Ekim'!BN6:BN20) | E35: =SUM('Ekim'!BO6:BO20) | F35: =SUM('Ekim'!BP6:BP20) | G35: =SUM('Ekim'!BQ6:BQ20) | H35: =SUM('Ekim'!BR6:BR20) | I35: =IF(D35+E35+F35=0,"",G35/(D35+E35+F35))
A36: Kasım | C36: 30 | D36: =SUM('Kasım'!BL6:BL20) | E36: =SUM('Kasım'!BM6:BM20) | F36: =SUM('Kasım'!BN6:BN20) | G36: =SUM('Kasım'!BO6:BO20) | H36: =SUM('Kasım'!BP6:BP20) | I36: =IF(D36+E36+F36=0,"",G36/(D36+E36+F36))
A37: Aralık | C37: 31 | D37: =SUM('Aralık'!BN6:BN20) | E37: =SUM('Aralık'!BO6:BO20) | F37: =SUM('Aralık'!BP6:BP20) | G37: =SUM('Aralık'!BQ6:BQ20) | H37: =SUM('Aralık'!BR6:BR20) | I37: =IF(D37+E37+F37=0,"",G37/(D37+E37+F37))
A38: YIL TOPLAMI | C38: =SUM(C26:C37) | D38: =SUM(D26:D37) | E38: =SUM(E26:E37) | F38: =SUM(F26:F37) | G38: =SUM(G26:G37) | H38: =SUM(H26:H37) | I38: =IF(D38+E38+F38=0,"",G38/(D38+E38+F38))

Sheet Personel_Listesi
A1: 2026 PERSONEL LİSTESİ
A2: Personel bilgilerini yalnızca bu sayfaya girin; tüm ay sayfaları ve yıllık rapor otomatik güncellenir. Ad Soyad BÜYÜK HARF yazılmalıdır.
A4: Sicil No | B4: Ad Soyad | C4: Departman
A5: 1001 | B5: AHMET YILMAZ | C5: Üretim
A6: 1002 | B6: AYŞE DEMIR | C6: Muhasebe
A7: 1003 | B7: MEHMET KAYA | C7: Lojistik
A8: 1004 | B8: FATMA ŞAHIN | C8: İnsan Kaynakları
A9: 1005 | B9: MUSTAFA ÇELIK | C9: Üretim
A10: 1006 | B10: ZEYNEP ARSLAN | C10: Satış
A11: 1007 | B11: EMRE ÖZTÜRK | C11: Bakım-Onarım

Sheet Ocak
A1: OCAK 2026 — PERSONEL PUANTAJ VE MESAİ ÇİZELGESİ
A2: Takvim gün sayısı: 31 | Durum kodları → | D2: + Geldi | I2: x Yarım Gün | N2: - Gelmedi
A4: Sicil No | B4: Ad Soyad | C4: Departman | D4: 1 Per | F4: 2 Cum | H4: 3 Cmt | J4: 4 Paz | L4: 5 Pzt | N4: 6 Sal | P4: 7 Çar | R4: 8 Per | T4: 9 Cum | V4: 10 Cmt | X4: 11 Paz | Z4: 12 Pzt | AB4: 13 Sal | AD4: 14 Çar | AF4: 15 Per | AH4: 16 Cum | AJ4: 17 Cmt | AL4: 18 Paz | AN4: 19 Pzt | AP4: 20 Sal | AR4: 21 Çar | AT4: 22 Per | AV4: 23 Cum | AX4: 24 Cmt | AZ4: 25 Paz | BB4: 26 Pzt | BD4: 27 Sal | BF4: 28 Çar | BH4: 29 Per | BJ4: 30 Cum | BL4: 31 Cmt | BN4: Tam Gün (+) | BO4: Yarım Gün (x) | BP4: Gelmediği Gün (-) | BQ4: Fiili Çalışılan Gün | BR4: Toplam Mesai (Saat)
D5: Drm | E5: Mesai | F5: Drm | G5: Mesai | H5: Drm | I5: Mesai | J5: Drm | K5: Mesai | L5: Drm | M5: Mesai | N5: Drm | O5: Mesai | P5: Drm | Q5: Mesai | R5: Drm | S5: Mesai | T5: Drm | U5: Mesai | V5: Drm | W5: Mesai | X5: Drm | Y5: Mesai | Z5: Drm | AA5: Mesai | AB5: Drm | AC5: Mesai | AD5: Drm | AE5: Mesai | AF5: Drm | AG5: Mesai | AH5: Drm | AI5: Mesai | AJ5: Drm | AK5: Mesai | AL5: Drm | AM5: Mesai | AN5: Drm | AO5: Mesai | AP5: Drm | AQ5: Mesai | AR5: Drm | AS5: Mesai | AT5: Drm | AU5: Mesai | AV5: Drm | AW5: Mesai | AX5: Drm | AY5: Mesai | AZ5: Drm | BA5: Mesai | BB5: Drm | BC5: Mesai | BD5: Drm | BE5: Mesai | BF5: Drm | BG5: Mesai | BH5: Drm | BI5: Mesai | BJ5: Drm | BK5: Mesai | BL5: Drm | BM5: Mesai
A6: =IF(Personel_Listesi!A5="","",Personel_Listesi!A5) | B6: =IF(Personel_Listesi!B5="","",UPPER(Personel_Listesi!B5)) | C6: =IF(Personel_Listesi!C5="","",Personel_Listesi!C5) | D6: x | F6: + | L6: + | N6: + | O6: 1 | P6: + | R6: + | T6: - | Z6: x | AB6: + | AC6: 1 | AD6: - | AF6: x | AH6: - | AN6: + | AP6: + | AR6: + | AT6: x | AV6: + | BB6: + | BD6: + | BF6: + | BH6: + | BJ6: + | BN6: =IF($A6="","",COUNTIF(D6:BM6,"+")) | BO6: =IF($A6="","",COUNTIF(D6:BM6,"x")) | BP6: =IF($A6="","",COUNTIF(D6:BM6,"-")) | BQ6: =IF($A6="","",BN6+BO6*0.5) | BR6: =IF($A6="","",SUM(E6,G6,I6,K6,M6,O6,Q6,S6,U6,W6,Y6,AA6,AC6,AE6,AG6,AI6,AK6,AM6,AO6,AQ6,AS6,AU6,AW6,AY6,BA6,BC6,BE6,BG6,BI6,BK6,BM6))
A7: =IF(Personel_Listesi!A6="","",Personel_Listesi!A6) | B7: =IF(Personel_Listesi!B6="","",UPPER(Personel_Listesi!B6)) | C7: =IF(Personel_Listesi!C6="","",Personel_Listesi!C6) | D7: + | F7: - | L7: + | M7: 1.5 | N7: + | O7: 2.5 | P7: + | Q7: 1.5 | R7: + | T7: + | Z7: + | AA7: 2 | AB7: + | AD7: + | AE7: 2.5 | AF7: + | AH7: + | AN7: + | AP7: + | AR7: + | AS7: 1.5 | AT7: + | AU7: 2 | AV7: - | BB7: + | BD7: + | BF7: + | BG7: 3 | BH7: + | BJ7: + | BK7: 1.5 | BN7: =IF($A7="","",COUNTIF(D7:BM7,"+")) | BO7: =IF($A7="","",COUNTIF(D7:BM7,"x")) | BP7: =IF($A7="","",COUNTIF(D7:BM7,"-")) | BQ7: =IF($A7="","",BN7+BO7*0.5) | BR7: =IF($A7="","",SUM(E7,G7,I7,K7,M7,O7,Q7,S7,U7,W7,Y7,AA7,AC7,AE7,AG7,AI7,AK7,AM7,AO7,AQ7,AS7,AU7,AW7,AY7,BA7,BC7,BE7,BG7,BI7,BK7,BM7))
A8: =IF(Personel_Listesi!A7="","",Personel_Listesi!A7) | B8: =IF(Personel_Listesi!B7="","",UPPER(Personel_Listesi!B7)) | C8: =IF(Personel_Listesi!C7="","",Personel_Listesi!C7) | D8: + | F8: + | L8: + | N8: + | O8: 2 | P8: - | R8: + | T8: + | U8: 2.5 | Z8: + | AB8: + | AD8: + | AF8: - | AH8: - | AN8: + | AP8: + | AR8: + | AT8: + | AV8: + | AW8: 1 | BB8: + | BD8: + | BF8: + | BH8: + | BI8: 2 | BJ8: + | BK8: 3 | BN8: =IF($A8="","",COUNTIF(D8:BM8,"+")) | BO8: =IF($A8="","",COUNTIF(D8:BM8,"x")) | BP8: =IF($A8="","",COUNTIF(D8:BM8,"-")) | BQ8: =IF($A8="","",BN8+BO8*0.5) | BR8: =IF($A8="","",SUM(E8,G8,I8,K8,M8,O8,Q8,S8,U8,W8,Y8,AA8,AC8,AE8,AG8,AI8,AK8,AM8,AO8,AQ8,AS8,AU8,AW8,AY8,BA8,BC8,BE8,BG8,BI8,BK8,BM8))
A9: =IF(Personel_Listesi!A8="","",Personel_Listesi!A8) | B9: =IF(Personel_Listesi!B8="","",UPPER(Personel_Listesi!B8)) | C9: =IF(Personel_Listesi!C8="","",Personel_Listesi!C8) | D9: + | F9: + | L9: + | M9: 2 | N9: x | P9: + | Q9: 2.5 | R9: + | T9: + | Z9: + | AB9: + | AC9: 3 | AD9: + | AF9: + | AH9: x | AN9: + | AO9: 3 | AP9: + | AQ9: 2 | AR9: + | AT9: + | AV9: + | BB9: + | BD9: + | BE9: 1 | BF9: + | BH9: + | BJ9: + | BN9: =IF($A9="","",COUNTIF(D9:BM9,"+")) | BO9: =IF($A9="","",COUNTIF(D9:BM9,"x")) | BP9: =IF($A9="","",COUNTIF(D9:BM9,"-")) | BQ9: =IF($A9="","",BN9+BO9*0.5) | BR9: =IF($A9="","",SUM(E9,G9,I9,K9,M9,O9,Q9,S9,U9,W9,Y9,AA9,AC9,AE9,AG9,AI9,AK9,AM9,AO9,AQ9,AS9,AU9,AW9,AY9,BA9,BC9,BE9,BG9,BI9,BK9,BM9))
A10: =IF(Personel_Listesi!A9="","",Personel_Listesi!A9) | B10: =IF(Personel_Listesi!B9="","",UPPER(Personel_Listesi!B9)) | C10: =IF(Personel_Listesi!C9="","",Personel_Listesi!C9) | D10: + | F10: + | G10: 1.5 | L10: - | N10: + | P10: + | R10: x | T10: + | Z10: + | AB10: + | AD10: x | AF10: + | AH10: + | AN10: + | AO10: 2 | AP10: + | AR10: + | AT10: + | AV10: + | BB10: + | BC10: 2 | BD10: + | BF10: + | BH10: + | BJ10: + | BN10: =IF($A10="","",COUNTIF(D10:BM10,"+")) | BO10: =IF($A10="","",COUNTIF(D10:BM10,"x")) | BP10: =IF($A10="","",COUNTIF(D10:BM10,"-")) | BQ10: =IF($A10="","",BN10+BO10*0.5) | BR10: =IF($A10="","",SUM(E10,G10,I10,K10,M10,O10,Q10,S10,U10,W10,Y10,AA10,AC10,AE10,AG10,AI10,AK10,AM10,AO10,AQ10,AS10,AU10,AW10,AY10,BA10,BC10,BE10,BG10,BI10,BK10,BM10))
A11: =IF(Personel_Listesi!A10="","",Personel_Listesi!A10) | B11: =IF(Personel_Listesi!B10="","",UPPER(Personel_Listesi!B10)) | C11: =IF(Personel_Listesi!C10="","",Personel_Listesi!C10) | D11: + | E11: 2.5 | F11: + | L11: + | N11: + | O11: 2 | P11: + | R11: - | T11: + | Z11: + | AB11: + | AC11: 2 | AD11: + | AF11: + | AH11: + | AN11: + | AP11: x | AR11: + | AT11: + | AV11: + | AW11: 1.5 | BB11: + | BC11: 1.5 | BD11: + | BE11: 1.5 | BF11: + | BH11: + | BJ11: + | BN11: =IF($A11="","",COUNTIF(D11:BM11,"+")) | BO11: =IF($A11="","",COUNTIF(D11:BM11,"x")) | BP11: =IF($A11="","",COUNTIF(D11:BM11,"-")) | BQ11: =IF($A11="","",BN11+BO11*0.5) | BR11: =IF($A11="","",SUM(E11,G11,I11,K11,M11,O11,Q11,S11,U11,W11,Y11,AA11,AC11,AE11,AG11,AI11,AK11,AM11,AO11,AQ11,AS11,AU11,AW11,AY11,BA11,BC11,BE11,BG11,BI11,BK11,BM11))
A12: =IF(Personel_Listesi!A11="","",Personel_Listesi!A11) | B12: =IF(Personel_Listesi!B11="","",UPPER(Personel_Listesi!B11)) | C12: =IF(Personel_Listesi!C11="","",Personel_Listesi!C11) | D12: x | F12: + | G12: 2 | L12: + | M12: 1.5 | N12: + | O12: 3 | P12: + | R12: + | S12: 1 | T12: + | Z12: - | AB12: + | AC12: 2 | AD12: + | AF12: + | AG12: 1.5 | AH12: + | AN12: + | AO12: 2.5 | AP12: + | AQ12: 1 | AR12: + | AS12: 2.5 | AT12: + | AV12: + | BB12: + | BC12: 2 | BD12: + | BF12: x | BH12: + | BJ12: + | BK12: 2 | BN12: =IF($A12="","",COUNTIF(D12:BM12,"+")) | BO12: =IF($A12="","",COUNTIF(D12:BM12,"x")) | BP12: =IF($A12="","",COUNTIF(D12:BM12,"-")) | BQ12: =IF($A12="","",BN12+BO12*0.5) | BR12: =IF($A12="","",SUM(E12,G12,I12,K12,M12,O12,Q12,S12,U12,W12,Y12,AA12,AC12,AE12,AG12,AI12,AK12,AM12,AO12,AQ12,AS12,AU12,AW12,AY12,BA12,BC12,BE12,BG12,BI12,BK12,BM12))
A13: =IF(Personel_Listesi!A12="","",Personel_Listesi!A12) | B13: =IF(Personel_Listesi!B12="","",UPPER(Personel_Listesi!B12)) | C13: =IF(Personel_Listesi!C12="","",Personel_Listesi!C12) | BN13: =IF($A13="","",COUNTIF(D13:BM13,"+")) | BO13: =IF($A13="","",COUNTIF(D13:BM13,"x")) | BP13: =IF($A13="","",COUNTIF(D13:BM13,"-")) | BQ13: =IF($A13="","",BN13+BO13*0.5) | BR13: =IF($A13="","",SUM(E13,G13,I13,K13,M13,O13,Q13,S13,U13,W13,Y13,AA13,AC13,AE13,AG13,AI13,AK13,AM13,AO13,AQ13,AS13,AU13,AW13,AY13,BA13,BC13,BE13,BG13,BI13,BK13,BM13))
A14: =IF(Personel_Listesi!A13="","",Personel_Listesi!A13) | B14: =IF(Personel_Listesi!B13="","",UPPER(Personel_Listesi!B13)) | C14: =IF(Personel_Listesi!C13="","",Personel_Listesi!C13) | BN14: =IF($A14="","",COUNTIF(D14:BM14,"+")) | BO14: =IF($A14="","",COUNTIF(D14:BM14,"x")) | BP14: =IF($A14="","",COUNTIF(D14:BM14,"-")) | BQ14: =IF($A14="","",BN14+BO14*0.5) | BR14: =IF($A14="","",SUM(E14,G14,I14,K14,M14,O14,Q14,S14,U14,W14,Y14,AA14,AC14,AE14,AG14,AI14,AK14,AM14,AO14,AQ14,AS14,AU14,AW14,AY14,BA14,BC14,BE14,BG14,BI14,BK14,BM14))
A15: =IF(Personel_Listesi!A14="","",Personel_Listesi!A14) | B15: =IF(Personel_Listesi!B14="","",UPPER(Personel_Listesi!B14)) | C15: =IF(Personel_Listesi!C14="","",Personel_Listesi!C14) | BN15: =IF($A15="","",COUNTIF(D15:BM15,"+")) | BO15: =IF($A15="","",COUNTIF(D15:BM15,"x")) | BP15: =IF($A15="","",COUNTIF(D15:BM15,"-")) | BQ15: =IF($A15="","",BN15+BO15*0.5) | BR15: =IF($A15="","",SUM(E15,G15,I15,K15,M15,O15,Q15,S15,U15,W15,Y15,AA15,AC15,AE15,AG15,AI15,AK15,AM15,AO15,AQ15,AS15,AU15,AW15,AY15,BA15,BC15,BE15,BG15,BI15,BK15,BM15))
A16: =IF(Personel_Listesi!A15="","",Personel_Listesi!A15) | B16: =IF(Personel_Listesi!B15="","",UPPER(Personel_Listesi!B15)) | C16: =IF(Personel_Listesi!C15="","",Personel_Listesi!C15) | BN16: =IF($A16="","",COUNTIF(D16:BM16,"+")) | BO16: =IF($A16="","",COUNTIF(D16:BM16,"x")) | BP16: =IF($A16="","",COUNTIF(D16:BM16,"-")) | BQ16: =IF($A16="","",BN16+BO16*0.5) | BR16: =IF($A16="","",SUM(E16,G16,I16,K16,M16,O16,Q16,S16,U16,W16,Y16,AA16,AC16,AE16,AG16,AI16,AK16,AM16,AO16,AQ16,AS16,AU16,AW16,AY16,BA16,BC16,BE16,BG16,BI16,BK16,BM16))
A17: =IF(Personel_Listesi!A16="","",Personel_Listesi!A16) | B17: =IF(Personel_Listesi!B16="","",UPPER(Personel_Listesi!B16)) | C17: =IF(Personel_Listesi!C16="","",Personel_Listesi!C16) | BN17: =IF($A17="","",COUNTIF(D17:BM17,"+")) | BO17: =IF($A17="","",COUNTIF(D17:BM17,"x")) | BP17: =IF($A17="","",COUNTIF(D17:BM17,"-")) | BQ17: =IF($A17="","",BN17+BO17*0.5) | BR17: =IF($A17="","",SUM(E17,G17,I17,K17,M17,O17,Q17,S17,U17,W17,Y17,AA17,AC17,AE17,AG17,AI17,AK17,AM17,AO17,AQ17,AS17,AU17,AW17,AY17,BA17,BC17,BE17,BG17,BI17,BK17,BM17))
A18: =IF(Personel_Listesi!A17="","",Personel_Listesi!A17) | B18: =IF(Personel_Listesi!B17="","",UPPER(Personel_Listesi!B17)) | C18: =IF(Personel_Listesi!C17="","",Personel_Listesi!C17) | BN18: =IF($A18="","",COUNTIF(D18:BM18,"+")) | BO18: =IF($A18="","",COUNTIF(D18:BM18,"x")) | BP18: =IF($A18="","",COUNTIF(D18:BM18,"-")) | BQ18: =IF($A18="","",BN18+BO18*0.5) | BR18: =IF($A18="","",SUM(E18,G18,I18,K18,M18,O18,Q18,S18,U18,W18,Y18,AA18,AC18,AE18,AG18,AI18,AK18,AM18,AO18,AQ18,AS18,AU18,AW18,AY18,BA18,BC18,BE18,BG18,BI18,BK18,BM18))
A19: =IF(Personel_Listesi!A18="","",Personel_Listesi!A18) | B19: =IF(Personel_Listesi!B18="","",UPPER(Personel_Listesi!B18)) | C19: =IF(Personel_Listesi!C18="","",Personel_Listesi!C18) | BN19: =IF($A19="","",COUNTIF(D19:BM19,"+")) | BO19: =IF($A19="","",COUNTIF(D19:BM19,"x")) | BP19: =IF($A19="","",COUNTIF(D19:BM19,"-")) | BQ19: =IF($A19="","",BN19+BO19*0.5) | BR19: =IF($A19="","",SUM(E19,G19,I19,K19,M19,O19,Q19,S19,U19,W19,Y19,AA19,AC19,AE19,AG19,AI19,AK19,AM19,AO19,AQ19,AS19,AU19,AW19,AY19,BA19,BC19,BE19,BG19,BI19,BK19,BM19))
A20: =IF(Personel_Listesi!A19="","",Personel_Listesi!A19) | B20: =IF(Personel_Listesi!B19="","",UPPER(Personel_Listesi!B19)) | C20: =IF(Personel_Listesi!C19="","",Personel_Listesi!C19) | BN20: =IF($A20="","",COUNTIF(D20:BM20,"+")) | BO20: =IF($A20="","",COUNTIF(D20:BM20,"x")) | BP20: =IF($A20="","",COUNTIF(D20:BM20,"-")) | BQ20: =IF($A20="","",BN20+BO20*0.5) | BR20: =IF($A20="","",SUM(E20,G20,I20,K20,M20,O20,Q20,S20,U20,W20,Y20,AA20,AC20,AE20,AG20,AI20,AK20,AM20,AO20,AQ20,AS20,AU20,AW20,AY20,BA20,BC20,BE20,BG20,BI20,BK20,BM20))

Sheet Şubat
A1: ŞUBAT 2026 — PERSONEL PUANTAJ VE MESAİ ÇİZELGESİ
A2: Takvim gün sayısı: 28 | Durum kodları → | D2: + Geldi | I2: x Yarım Gün | N2: - Gelmedi
A4: Sicil No | B4: Ad Soyad | C4: Departman | D4: 1 Paz | F4: 2 Pzt | H4: 3 Sal | J4: 4 Çar | L4: 5 Per | N4: 6 Cum | P4: 7 Cmt | R4: 8 Paz | T4: 9 Pzt | V4: 10 Sal | X4: 11 Çar | Z4: 12 Per | AB4: 13 Cum | AD4: 14 Cmt | AF4: 15 Paz | AH4: 16 Pzt | AJ4: 17 Sal | AL4: 18 Çar | AN4: 19 Per | AP4: 20 Cum | AR4: 21 Cmt | AT4: 22 Paz | AV4: 23 Pzt | AX4: 24 Sal | AZ4: 25 Çar | BB4: 26 Per | BD4: 27 Cum | BF4: 28 Cmt | BH4: Tam Gün (+) | BI4: Yarım Gün (x) | BJ4: Gelmediği Gün (-) | BK4: Fiili Çalışılan Gün | BL4: Toplam Mesai (Saat)
D5: Drm | E5: Mesai | F5: Drm | G5: Mesai | H5: Drm | I5: Mesai | J5: Drm | K5: Mesai | L5: Drm | M5: Mesai | N5: Drm | O5: Mesai | P5: Drm | Q5: Mesai | R5: Drm | S5: Mesai | T5: Drm | U5: Mesai | V5: Drm | W5: Mesai | X5: Drm | Y5: Mesai | Z5: Drm | AA5: Mesai | AB5: Drm | AC5: Mesai | AD5: Drm | AE5: Mesai | AF5: Drm | AG5: Mesai | AH5: Drm | AI5: Mesai | AJ5: Drm | AK5: Mesai | AL5: Drm | AM5: Mesai | AN5: Drm | AO5: Mesai | AP5: Drm | AQ5: Mesai | AR5: Drm | AS5: Mesai | AT5: Drm | AU5: Mesai | AV5: Drm | AW5: Mesai | AX5: Drm | AY5: Mesai | AZ5: Drm | BA5: Mesai | BB5: Drm | BC5: Mesai | BD5: Drm | BE5: Mesai | BF5: Drm | BG5: Mesai
A6: =IF(Personel_Listesi!A5="","",Personel_Listesi!A5) | B6: =IF(Personel_Listesi!B5="","",UPPER(Personel_Listesi!B5)) | C6: =IF(Personel_Listesi!C5="","",Personel_Listesi!C5) | BH6: =IF($A6="","",COUNTIF(D6:BG6,"+")) | BI6: =IF($A6="","",COUNTIF(D6:BG6,"x")) | BJ6: =IF($A6="","",COUNTIF(D6:BG6,"-")) | BK6: =IF($A6="","",BH6+BI6*0.5) | BL6: =IF($A6="","",SUM(E6,G6,I6,K6,M6,O6,Q6,S6,U6,W6,Y6,AA6,AC6,AE6,AG6,AI6,AK6,AM6,AO6,AQ6,AS6,AU6,AW6,AY6,BA6,BC6,BE6,BG6))
A7: =IF(Personel_Listesi!A6="","",Personel_Listesi!A6) | B7: =IF(Personel_Listesi!B6="","",UPPER(Personel_Listesi!B6)) | C7: =IF(Personel_Listesi!C6="","",Personel_Listesi!C6) | BH7: =IF($A7="","",COUNTIF(D7:BG7,"+")) | BI7: =IF($A7="","",COUNTIF(D7:BG7,"x")) | BJ7: =IF($A7="","",COUNTIF(D7:BG7,"-")) | BK7: =IF($A7="","",BH7+BI7*0.5) | BL7: =IF($A7="","",SUM(E7,G7,I7,K7,M7,O7,Q7,S7,U7,W7,Y7,AA7,AC7,AE7,AG7,AI7,AK7,AM7,AO7,AQ7,AS7,AU7,AW7,AY7,BA7,BC7,BE7,BG7))
A8: =IF(Personel_Listesi!A7="","",Personel_Listesi!A7) | B8: =IF(Personel_Listesi!B7="","",UPPER(Personel_Listesi!B7)) | C8: =IF(Personel_Listesi!C7="","",Personel_Listesi!C7) | BH8: =IF($A8="","",COUNTIF(D8:BG8,"+")) | BI8: =IF($A8="","",COUNTIF(D8:BG8,"x")) | BJ8: =IF($A8="","",COUNTIF(D8:BG8,"-")) | BK8: =IF($A8="","",BH8+BI8*0.5) | BL8: =IF($A8="","",SUM(E8,G8,I8,K8,M8,O8,Q8,S8,U8,W8,Y8,AA8,AC8,AE8,AG8,AI8,AK8,AM8,AO8,AQ8,AS8,AU8,AW8,AY8,BA8,BC8,BE8,BG8))
A9: =IF(Personel_Listesi!A8="","",Personel_Listesi!A8) | B9: =IF(Personel_Listesi!B8="","",UPPER(Personel_Listesi!B8)) | C9: =IF(Personel_Listesi!C8="","",Personel_Listesi!C8) | BH9: =IF($A9="","",COUNTIF(D9:BG9,"+")) | BI9: =IF($A9="","",COUNTIF(D9:BG9,"x")) | BJ9: =IF($A9="","",COUNTIF(D9:BG9,"-")) | BK9: =IF($A9="","",BH9+BI9*0.5) | BL9: =IF($A9="","",SUM(E9,G9,I9,K9,M9,O9,Q9,S9,U9,W9,Y9,AA9,AC9,AE9,AG9,AI9,AK9,AM9,AO9,AQ9,AS9,AU9,AW9,AY9,BA9,BC9,BE9,BG9))
A10: =IF(Personel_Listesi!A9="","",Personel_Listesi!A9) | B10: =IF(Personel_Listesi!B9="","",UPPER(Personel_Listesi!B9)) | C10: =IF(Personel_Listesi!C9="","",Personel_Listesi!C9) | BH10: =IF($A10="","",COUNTIF(D10:BG10,"+")) | BI10: =IF($A10="","",COUNTIF(D10:BG10,"x")) | BJ10: =IF($A10="","",COUNTIF(D10:BG10,"-")) | BK10: =IF($A10="","",BH10+BI10*0.5) | BL10: =IF($A10="","",SUM(E10,G10,I10,K10,M10,O10,Q10,S10,U10,W10,Y10,AA10,AC10,AE10,AG10,AI10,AK10,AM10,AO10,AQ10,AS10,AU10,AW10,AY10,BA10,BC10,BE10,BG10))
A11: =IF(Personel_Listesi!A10="","",Personel_Listesi!A10) | B11: =IF(Personel_Listesi!B10="","",UPPER(Personel_Listesi!B10)) | C11: =IF(Personel_Listesi!C10="","",Personel_Listesi!C10) | BH11: =IF($A11="","",COUNTIF(D11:BG11,"+")) | BI11: =IF($A11="","",COUNTIF(D11:BG11,"x")) | BJ11: =IF($A11="","",COUNTIF(D11:BG11,"-")) | BK11: =IF($A11="","",BH11+BI11*0.5) | BL11: =IF($A11="","",SUM(E11,G11,I11,K11,M11,O11,Q11,S11,U11,W11,Y11,AA11,AC11,AE11,AG11,AI11,AK11,AM11,AO11,AQ11,AS11,AU11,AW11,AY11,BA11,BC11,BE11,BG11))
A12: =IF(Personel_Listesi!A11="","",Personel_Listesi!A11) | B12: =IF(Personel_Listesi!B11="","",UPPER(Personel_Listesi!B11)) | C12: =IF(Personel_Listesi!C11="","",Personel_Listesi!C11) | BH12: =IF($A12="","",COUNTIF(D12:BG12,"+")) | BI12: =IF($A12="","",COUNTIF(D12:BG12,"x")) | BJ12: =IF($A12="","",COUNTIF(D12:BG12,"-")) | BK12: =IF($A12="","",BH12+BI12*0.5) | BL12: =IF($A12="","",SUM(E12,G12,I12,K12,M12,O12,Q12,S12,U12,W12,Y12,AA12,AC12,AE12,AG12,AI12,AK12,AM12,AO12,AQ12,AS12,AU12,AW12,AY12,BA12,BC12,BE12,BG12))
A13: =IF(Personel_Listesi!A12="","",Personel_Listesi!A12) | B13: =IF(Personel_Listesi!B12="","",UPPER(Personel_Listesi!B12)) | C13: =IF(Personel_Listesi!C12="","",Personel_Listesi!C12) | BH13: =IF($A13="","",COUNTIF(D13:BG13,"+")) | BI13: =IF($A13="","",COUNTIF(D13:BG13,"x")) | BJ13: =IF($A13="","",COUNTIF(D13:BG13,"-")) | BK13: =IF($A13="","",BH13+BI13*0.5) | BL13: =IF($A13="","",SUM(E13,G13,I13,K13,M13,O13,Q13,S13,U13,W13,Y13,AA13,AC13,AE13,AG13,AI13,AK13,AM13,AO13,AQ13,AS13,AU13,AW13,AY13,BA13,BC13,BE13,BG13))
A14: =IF(Personel_Listesi!A13="","",Personel_Listesi!A13) | B14: =IF(Personel_Listesi!B13="","",UPPER(Personel_Listesi!B13)) | C14: =IF(Personel_Listesi!C13="","",Personel_Listesi!C13) | BH14: =IF($A14="","",COUNTIF(D14:BG14,"+")) | BI14: =IF($A14="","",COUNTIF(D14:BG14,"x")) | BJ14: =IF($A14="","",COUNTIF(D14:BG14,"-")) | BK14: =IF($A14="","",BH14+BI14*0.5) | BL14: =IF($A14="","",SUM(E14,G14,I14,K14,M14,O14,Q14,S14,U14,W14,Y14,AA14,AC14,AE14,AG14,AI14,AK14,AM14,AO14,AQ14,AS14,AU14,AW14,AY14,BA14,BC14,BE14,BG14))
A15: =IF(Personel_Listesi!A14="","",Personel_Listesi!A14) | B15: =IF(Personel_Listesi!B14="","",UPPER(Personel_Listesi!B14)) | C15: =IF(Personel_Listesi!C14="","",Personel_Listesi!C14) | BH15: =IF($A15="","",COUNTIF(D15:BG15,"+")) | BI15: =IF($A15="","",COUNTIF(D15:BG15,"x")) | BJ15: =IF($A15="","",COUNTIF(D15:BG15,"-")) | BK15: =IF($A15="","",BH15+BI15*0.5) | BL15: =IF($A15="","",SUM(E15,G15,I15,K15,M15,O15,Q15,S15,U15,W15,Y15,AA15,AC15,AE15,AG15,AI15,AK15,AM15,AO15,AQ15,AS15,AU15,AW15,AY15,BA15,BC15,BE15,BG15))
A16: =IF(Personel_Listesi!A15="","",Personel_Listesi!A15) | B16: =IF(Personel_Listesi!B15="","",UPPER(Personel_Listesi!B15)) | C16: =IF(Personel_Listesi!C15="","",Personel_Listesi!C15) | BH16: =IF($A16="","",COUNTIF(D16:BG16,"+")) | BI16: =IF($A16="","",COUNTIF(D16:BG16,"x")) | BJ16: =IF($A16="","",COUNTIF(D16:BG16,"-")) | BK16: =IF($A16="","",BH16+BI16*0.5) | BL16: =IF($A16="","",SUM(E16,G16,I16,K16,M16,O16,Q16,S16,U16,W16,Y16,AA16,AC16,AE16,AG16,AI16,AK16,AM16,AO16,AQ16,AS16,AU16,AW16,AY16,BA16,BC16,BE16,BG16))
A17: =IF(Personel_Listesi!A16="","",Personel_Listesi!A16) | B17: =IF(Personel_Listesi!B16="","",UPPER(Personel_Listesi!B16)) | C17: =IF(Personel_Listesi!C16="","",Personel_Listesi!C16) | BH17: =IF($A17="","",COUNTIF(D17:BG17,"+")) | BI17: =IF($A17="","",COUNTIF(D17:BG17,"x")) | BJ17: =IF($A17="","",COUNTIF(D17:BG17,"-")) | BK17: =IF($A17="","",BH17+BI17*0.5) | BL17: =IF($A17="","",SUM(E17,G17,I17,K17,M17,O17,Q17,S17,U17,W17,Y17,AA17,AC17,AE17,AG17,AI17,AK17,AM17,AO17,AQ17,AS17,AU17,AW17,AY17,BA17,BC17,BE17,BG17))
... A20: =IF(Personel_Listesi!A19="","",Personel_Listesi!A19) | B20: =IF(Personel_Listesi!B19="","",UPPER(Personel_Listesi!B19)) | C20: =IF(Personel_Listesi!C19="","",Personel_Listesi!C19) | BH20: =IF($A20="","",COUNTIF(D20:BG20,"+")) | BI20: =IF($A20="","",COUNTIF(D20:BG20,"x")) | BJ20: =IF($A20="","",COUNTIF(D20:BG20,"-")) | BK20: =IF($A20="","",BH20+BI20*0.5) | BL20: =IF($A20="","",SUM(E20,G20,I20,K20,M20,O20,Q20,S20,U20,W20,Y20,AA20,AC20,AE20,AG20,AI20,AK20,AM20,AO20,AQ20,AS20,AU20,AW20,AY20,BA20,BC20,BE20,BG20))

Sheet Mart
A1: MART 2026 — PERSONEL PUANTAJ VE MESAİ ÇİZELGESİ
A2: Takvim gün sayısı: 31 | Durum kodları → | D2: + Geldi | I2: x Yarım Gün | N2: - Gelmedi
A4: Sicil No | B4: Ad Soyad | C4: Departman | D4: 1 Paz | F4: 2 Pzt | H4: 3 Sal | J4: 4 Çar | L4: 5 Per | N4: 6 Cum | P4: 7 Cmt | R4: 8 Paz | T4: 9 Pzt | V4: 10 Sal | X4: 11 Çar | Z4: 12 Per | AB4: 13 Cum | AD4: 14 Cmt | AF4: 15 Paz | AH4: 16 Pzt | AJ4: 17 Sal | AL4: 18 Çar | AN4: 19 Per | AP4: 20 Cum | AR4: 21 Cmt | AT4: 22 Paz | AV4: 23 Pzt | AX4: 24 Sal | AZ4: 25 Çar | BB4: 26 Per | BD4: 27 Cum | BF4: 28 Cmt | BH4: 29 Paz | BJ4: 30 Pzt | BL4: 31 Sal | BN4: Tam Gün (+) | BO4: Yarım Gün (x) | BP4: Gelmediği Gün (-) | BQ4: Fiili Çalışılan Gün | BR4: Toplam Mesai (Saat)
D5: Drm | E5: Mesai | F5: Drm | G5: Mesai | H5: Drm | I5: Mesai | J5: Drm | K5: Mesai | L5: Drm | M5: Mesai | N5: Drm | O5: Mesai | P5: Drm | Q5: Mesai | R5: Drm | S5: Mesai | T5: Drm | U5: Mesai | V5: Drm | W5: Mesai | X5: Drm | Y5: Mesai | Z5: Drm | AA5: Mesai | AB5: Drm | AC5: Mesai | AD5: Drm | AE5: Mesai | AF5: Drm | AG5: Mesai | AH5: Drm | AI5: Mesai | AJ5: Drm | AK5: Mesai | AL5: Drm | AM5: Mesai | AN5: Drm | AO5: Mesai | AP5: Drm | AQ5: Mesai | AR5: Drm | AS5: Mesai | AT5: Drm | AU5: Mesai | AV5: Drm | AW5: Mesai | AX5: Drm | AY5: Mesai | AZ5: Drm | BA5: Mesai | BB5: Drm | BC5: Mesai | BD5: Drm | BE5: Mesai | BF5: Drm | BG5: Mesai | BH5: Drm | BI5: Mesai | BJ5: Drm | BK5: Mesai | BL5: Drm | BM5: Mesai
A6: =IF(Personel_Listesi!A5="","",Personel_Listesi!A5) | B6: =IF(Personel_Listesi!B5="","",UPPER(Personel_Listesi!B5)) | C6: =IF(Personel_Listesi!C5="","",Personel_Listesi!C5) | BN6: =IF($A6="","",COUNTIF(D6:BM6,"+")) | BO6: =IF($A6="","",COUNTIF(D6:BM6,"x")) | BP6: =IF($A6="","",COUNTIF(D6:BM6,"-")) | BQ6: =IF($A6="","",BN6+BO6*0.5) | BR6: =IF($A6="","",SUM(E6,G6,I6,K6,M6,O6,Q6,S6,U6,W6,Y6,AA6,AC6,AE6,AG6,AI6,AK6,AM6,AO6,AQ6,AS6,AU6,AW6,AY6,BA6,BC6,BE6,BG6,BI6,BK6,BM6))
A7: =IF(Personel_Listesi!A6="","",Personel_Listesi!A6) | B7: =IF(Personel_Listesi!B6="","",UPPER(Personel_Listesi!B6)) | C7: =IF(Personel_Listesi!C6="","",Personel_Listesi!C6) | BN7: =IF($A7="","",COUNTIF(D7:BM7,"+")) | BO7: =IF($A7="","",COUNTIF(D7:BM7,"x")) | BP7: =IF($A7="","",COUNTIF(D7:BM7,"-")) | BQ7: =IF($A7="","",BN7+BO7*0.5) | BR7: =IF($A7="","",SUM(E7,G7,I7,K7,M7,O7,Q7,S7,U7,W7,Y7,AA7,AC7,AE7,AG7,AI7,AK7,AM7,AO7,AQ7,AS7,AU7,AW7,AY7,BA7,BC7,BE7,BG7,BI7,BK7,BM7))
